Workbook

Sheet GRAFIK
F1: DAILY SLA AVG BULAN DESEMBER 2025
B3: Baterai | C3: Total Site | D3: AVG SLA
B4: Talis5 Full | C4: ='Talis Full'!A1 -> 19 | D4: =AVERAGEIF(SLA!D:D,B4,SLA!H:H) -> 0.92730053
B5: Talis5 Mix | C5: ='Talis Mix'!A1 -> 15 | D5: =AVERAGEIF(SLA!D:D,B5,SLA!H:H) -> 0.81485488
B6: JS PRO | C6: ='JS PRO'!A1 -> 46 | D6: =AVERAGEIF(SLA!D:D,B6,SLA!H:H) -> 0.9163823
B8: TOTAL | C8: =SUM(C4:C6) -> 80 | D8: =SLA!H2 -> 0.90688193
B10: Baterai | C10: Penyebab AVG SLA masih dibawah 95.5%
B11: Talis5 Full | C11: SNMP DOWN
B12: Talis5 Mix | C12: Problem VSAT SNMP DOWN
B13: JS PRO | C13: Insiden terbakar Problem Vsat
B15: History GAMAS (Gangguan Masal)
B16: -
B36: *Tracking SLA avg daily bulan Desember 2025*
B37: =H37&" "&G37&" "&"/"&G38&"/"&G40 -> Tgl 1 - 8 /12/2025 | F37: =TODAY() -> 45999 | G37: =DAY(F37) -> 8 | H37: Tgl 1 -
B38: ="*"&"80 site"&"*" -> *80 site* | C38: ="*" & SUBSTITUTE(TEXT(F38, "0.00"), ".", ",") & "%" & "*" -> *90,69%* | F38: =D8*100 -> 90.688193 | G38: =MONTH(F37) -> 12
B40: =B4 -> Talis5 Full | C40: ="*" & SUBSTITUTE(TEXT(F40, "0.00"), ".", ",") & "%" & "*" -> *92,73%* | F40: =D4*100 -> 92.730053 | G40: =YEAR(F37) -> 2025
B41: =B5 -> Talis5 Mix | C41: ="*" & SUBSTITUTE(TEXT(F41, "0.00"), ".", ",") & "%" & "*" -> *81,49%* | F41: =D5*100 -> 81.485488
B42: =B6 -> JS PRO | C42: ="*" & SUBSTITUTE(TEXT(F42, "0.00"), ".", ",") & "%" & "*" -> *91,64%* | F42: =D6*100 -> 91.63823
B44: Trend SLA avg Bulan Desember 2025
B45: Minggu 1 | C45: =AVERAGE(SLA!J2:P2) -> 0.90688193
B46: Minggu 2 | C46: =AVERAGE(SLA!Q2:W2) -> #DIV/0!
B47: Minggu 3 | C47: =AVERAGE(SLA!X2:AD2) -> #DIV/0!
B48: Minggu 4 | C48: =AVERAGE(SLA!AE2:AM2) -> #DIV/0!

Sheet SLA
J1: https://docs.google.com/spreadsheets/d/1klpLbbl5DSHbiNwz8jHPLPE8mhHRawTOKn795joTXFw/edit?usp=sharing | K1: https://docs.google.com/spreadsheets/d/1kKhKU9XrjDhGOu5EkNUWQOZ1ZrPel-YbUb4bQ-yS45E/edit?usp=sharing | L1: https://docs.google.com/spreadsheets/d/14NdKGXXCTg0qub1jKzLHUFBr4zihZv7E8Opl8Qs-mVQ/edit?usp=sharing | M1: https://docs.google.com/spreadsheets/d/1n0dpf0G-7VNAgPCdli5FretXgDsHqInvDDuy18Q4GxU/edit?usp=sharing | N1: https://docs.google.com/spreadsheets/d/1S1w4agYvLlhtsLplO3baSIN0JNorp1EPIBYmH8eocHE/edit?usp=sharing | O1: https://docs.google.com/spreadsheets/d/1oZzSU9oXVKRbWr-FIVz676poc89Gcv_l5o6W2jydiUs/edit?usp=sharing | P1: https://docs.google.com/spreadsheets/d/1SvfV6O2h_kUIZJJu5ZqtVGE-LAFnD2jb_RyFIq-aVU0/edit?usp=sharing
H2: =AVERAGE(H4:H83) -> 0.90688193 | J2: =AVERAGE(J4:J83) -> 0.87714275 | K2: =IFERROR(AVERAGE(K4:K83), "") -> 0.89136688 | L2: =IFERROR(AVERAGE(L4:L83), "") -> 0.90098425 | M2: =IFERROR(AVERAGE(M4:M83), "") -> 0.89686075 | N2: =IFERROR(AVERAGE(N4:N83), "") -> 0.91271475 | O2: =IFERROR(AVERAGE(O4:O83), "") -> 0.93412237 | P2: =IFERROR(AVERAGE(P4:P83), "") -> 0.93498175 | Q2: =IFERROR(AVERAGE(Q4:Q83), "") | R2: =IFERROR(AVERAGE(R4:R83), "") | ... AN2: =IFERROR(AVERAGE(AN4:AN83), "")
A3: NAMA SITE | B3: PROVINSI | C3: KODE SITE | D3: BATERAI TYPE | E3: Done Instal (Talis) | F3: PIC | G3: PROBLEM | H3: SLA AVG | I3: Status | J3: 1 | K3: 2 | L3: 3 | M3: 4 | N3: 5 | O3: 6 | P3: 7 | Q3: 8 | R3: 9 | S3: 10 | T3: 11 | U3: 12 | V3: 13 | W3: 14 | X3: 15 | Y3: 16 | Z3: 17 | AA3: 18 | AB3: 19 | AC3: 20 | AD3: 21 | AE3: 22 | AF3: 23 | AG3: 24 | AH3: 25 | AI3: 26 | AJ3: 27 | AK3: 28 | AL3: 29 | AM3: 30 | AN3: 31
A4: MENARBU | B4: =IFERROR(__xludf.DUMMYFUNCTION("ARRAYFORMULA( IF($A4:$A999="""",, IFERROR( VLOOKUP( $A4:$A999, IMPORTRANGE(""https://docs.google.com/spreadsheets/d/1jUDLKEvnGsveFGtPfyfL3lhFTzPXQlZPIsYZzU_WHfo/edit?usp=sharing"",""Sheet1!B2:F""), 3, FALSE ), ) ))"),"PAPUA BARAT") -> PAPUA BARAT | C4: =IFERROR(__xludf.DUMMYFUNCTION("ARRAYFORMULA( IF($A4:$A999="""",, IFERROR( VLOOKUP( $A4:$A999, IMPORTRANGE(""https://docs.google.com/spreadsheets/d/1jUDLKEvnGsveFGtPfyfL3lhFTzPXQlZPIsYZzU_WHfo/edit?usp=sharing"",""Sheet1!B2:Z""), 25, FALSE ), ) ))"),"JS27") -> JS27 | D4: Talis5 Mix | E4: 45938 | G4: Vsat up down | H4: =AVERAGE(J4:AN4) -> 0.96378571 | I4: =IF(H4<75%, "Potensi SP", "") | J4: =IFERROR(__xludf.DUMMYFUNCTION("ARRAYFORMULA( IF($A4:$A999="""", """", IFNA( VLOOKUP( $A4:$A999, IMPORTRANGE(J1, ""Site OpExport!I:AS""), 37, FALSE ) / 100, """" ) ) )"),0.8541599999999999) -> 0.85416 | K4: =IFERROR(__xludf.DUMMYFUNCTION("ARRAYFORMULA( IF($A4:$A999="""", """", IFNA( VLOOKUP( $A4:$A999, IMPORTRANGE(K1, ""Site OpExport!I:AS""), 37, FALSE ) / 100, """" ) ) )"),0.9791500000000001) -> 0.97915 | L4: =IFERROR(__xludf.DUMMYFUNCTION("ARRAYFORMULA( IF($A4:$A999="""", """", IFNA( VLOOKUP( $A4:$A999, IMPORTRANGE(L1, ""Site OpExport!I:AS""), 37, FALSE ) / 100, """" ) ) )"),1.0) -> 1 | M4: =IFERROR(__xludf.DUMMYFUNCTION("ARRAYFORMULA( IF($A4:$A999="""", """", IFNA( VLOOKUP( $A4:$A999, IMPORTRANGE(M1, ""Site OpExport!I:AS""), 37, FALSE ) / 100, """" ) ) )"),1.0) -> 1 | N4: =IFERROR(__xludf.DUMMYFUNCTION("ARRAYFORMULA( IF($A4:$A999="""", """", IFNA( VLOOKUP( $A4:$A999, IMPORTRANGE(N1, ""Site OpExport!I:AS""), 37, FALSE ) / 100, """" ) ) )"),0.94098) -> 0.94098 | O4: =IFERROR(__xludf.DUMMYFUNCTION("ARRAYFORMULA( IF($A4:$A999="""", """", IFNA( VLOOKUP( $A4:$A999, IMPORTRANGE(O1, ""Site OpExport!I:AS""), 37, FALSE ) / 100, """" ) ) )"),0.9756900000000001) -> 0.97569 | P4: =IFERROR(__xludf.DUMMYFUNCTION("ARRAYFORMULA( IF($A4:$A999="""", """", IFNA( VLOOKUP( $A4:$A999, IMPORTRANGE(P1, ""Site OpExport!I:AS""), 37, FALSE ) / 100, """" ) ) )"),0.99652) -> 0.99652 | Q4: =IFERROR(__xludf.DUMMYFUNCTION("ARRAYFORMULA( IF($A4:$A999="""", """", IFNA( VLOOKUP( $A4:$A999, IMPORTRANGE(Q1, ""Site OpExport!I:AS""), 37, FALSE ) / 100, """" ) ) )"),"") | R4: =IFERROR(__xludf.DUMMYFUNCTION("ARRAYFORMULA( IF($A4:$A999="""", """", IFNA( VLOOKUP( $A4:$A999, IMPORTRANGE(R1, ""Site OpExport!I:AS""), 37, FALSE ) / 100, """" ) ) )"),"") | S4: =IFERROR(__xludf.DUMMYFUNCTION("ARRAYFORMULA( IF($A4:$A999="""", """", IFNA( VLOOKUP( $A4:$A999, IMPORTRANGE(S1, ""Site OpExport!I:AS""), 37, FALSE ) / 100, """" ) ) )"),"") | T4: =IFERROR(__xludf.DUMMYFUNCTION("ARRAYFORMULA( IF($A4:$A999="""", """", IFNA( VLOOKUP( $A4:$A999, IMPORTRANGE(T1, ""Site OpExport!I:AS""), 37, FALSE ) / 100, """" ) ) )"),"") | U4: =IFERROR(__xludf.DUMMYFUNCTION("ARRAYFORMULA( IF($A4:$A999="""", """", IFNA( VLOOKUP( $A4:$A999, IMPORTRANGE(U1, ""Site OpExport!I:AS""), 37, FALSE ) / 100, """" ) ) )"),"") | V4: =IFERROR(__xludf.DUMMYFUNCTION("ARRAYFORMULA( IF($A4:$A999="""", """", IFNA( VLOOKUP( $A4:$A999, IMPORTRANGE(V1, ""Site OpExport!I:AS""), 37, FALSE ) / 100, """" ) ) )"),"") | W4: =IFERROR(__xludf.DUMMYFUNCTION("ARRAYFORMULA( IF($A4:$A999="""", """", IFNA( VLOOKUP( $A4:$A999, IMPORTRANGE(W1, ""Site OpExport!I:AS""), 37, FALSE ) / 100, """" ) ) )"),"") | X4: =IFERROR(__xludf.DUMMYFUNCTION("ARRAYFORMULA( IF($A4:$A999="""", """", IFNA( VLOOKUP( $A4:$A999, IMPORTRANGE(X1, ""Site OpExport!I:AS""), 37, FALSE ) / 100, """" ) ) )"),"") | Y4: =IFERROR(__xludf.DUMMYFUNCTION("ARRAYFORMULA( IF($A4:$A999="""", """", IFNA( VLOOKUP( $A4:$A999, IMPORTRANGE(Y1, ""Site OpExport!I:AS""), 37, FALSE ) / 100, """" ) ) )"),"") | Z4: =IFERROR(__xludf.DUMMYFUNCTION("ARRAYFORMULA( IF($A4:$A999="""", """", IFNA( VLOOKUP( $A4:$A999, IMPORTRANGE(Z1, ""Site OpExport!I:AS""), 37, FALSE ) / 100, """" ) ) )"),"") | AA4: =IFERROR(__xludf.DUMMYFUNCTION("ARRAYFORMULA( IF($A4:$A999="""", """", IFNA( VLOOKUP( $A4:$A999, IMPORTRANGE(AA1, ""Site OpExport!I:AS""), 37, FALSE ) / 100, """" ) ) )"),"") | AB4: =IFERROR(__xludf.DUMMYFUNCTION("ARRAYFORMULA( IF($A4:$A999="""", """", IFNA( VLOOKUP( $A4:$A999, IMPORTRANGE(AB1, ""Site OpExport!I:AS""), 37, FALSE ) / 100, """" ) ) )"),"") | AC4: =IFERROR(__xludf.DUMMYFUNCTION("ARRAYFORMULA( IF($A4:$A999="""", """", IFNA( VLOOKUP( $A4:$A999, IMPORTRANGE(AC1, ""Site OpExport!I:AS""), 37, FALSE ) / 100, """" ) ) )"),"") | AD4: =IFERROR(__xludf.DUMMYFUNCTION("ARRAYFORMULA( IF($A4:$A999="""", """", IFNA( VLOOKUP( $A4:$A999, IMPORTRANGE(AD1, ""Site OpExport!I:AS""), 37, FALSE ) / 100, """" ) ) )"),"") | AE4: =IFERROR(__xludf.DUMMYFUNCTION("ARRAYFORMULA( IF($A4:$A999="""", """", IFNA( VLOOKUP( $A4:$A999, IMPORTRANGE(AE1, ""Site OpExport!I:AS""), 37, FALSE ) / 100, """" ) ) )"),"") | AF4: =IFERROR(__xludf.DUMMYFUNCTION("ARRAYFORMULA( IF($A4:$A999="""", """", IFNA( VLOOKUP( $A4:$A999, IMPORTRANGE(AF1, ""Site OpExport!I:AS""), 37, FALSE ) / 100, """" ) ) )"),"") | AG4: =IFERROR(__xludf.DUMMYFUNCTION("ARRAYFORMULA( IF($A4:$A999="""", """", IFNA( VLOOKUP( $A4:$A999, IMPORTRANGE(AG1, ""Site OpExport!I:AS""), 37, FALSE ) / 100, """" ) ) )"),"") | AH4: =IFERROR(__xludf.DUMMYFUNCTION("ARRAYFORMULA( IF($A4:$A999="""", """", IFNA( VLOOKUP( $A4:$A999, IMPORTRANGE(AH1, ""Site OpExport!I:AS""), 37, FALSE ) / 100, """" ) ) )"),"") | AI4: =IFERROR(__xludf.DUMMYFUNCTION("ARRAYFORMULA( IF($A4:$A999="""", """", IFNA( VLOOKUP( $A4:$A999, IMPORTRANGE(AI1, ""Site OpExport!I:AS""), 37, FALSE ) / 100, """" ) ) )"),"") | AJ4: =IFERROR(__xludf.DUMMYFUNCTION("ARRAYFORMULA( IF($A4:$A999="""", """", IFNA( VLOOKUP( $A4:$A999, IMPORTRANGE(AJ1, ""Site OpExport!I:AS""), 37, FALSE ) / 100, """" ) ) )"),"") | AK4: =IFERROR(__xludf.DUMMYFUNCTION("ARRAYFORMULA( IF($A4:$A999="""", """", IFNA( VLOOKUP( $A4:$A999, IMPORTRANGE(AK1, ""Site OpExport!I:AS""), 37, FALSE ) / 100, """" ) ) )"),"") | AL4: =IFERROR(__xludf.DUMMYFUNCTION("ARRAYFORMULA( IF($A4:$A999="""", """", IFNA( VLOOKUP( $A4:$A999, IMPORTRANGE(AL1, ""Site OpExport!I:AS""), 37, FALSE ) / 100, """" ) ) )"),"") | AM4: =IFERROR(__xludf.DUMMYFUNCTION("ARRAYFORMULA( IF($A4:$A999="""", """", IFNA( VLOOKUP( $A4:$A999, IMPORTRANGE(AM1, ""Site OpExport!I:AS""), 37, FALSE ) / 100, """" ) ) )"),"") | AN4: =IFERROR(__xludf.DUMMYFUNCTION("ARRAYFORMULA( IF($A4:$A999="""", """", IFNA( VLOOKUP( $A4:$A999, IMPORTRANGE(AN1, ""Site OpExport!I:AS""), 37, FALSE ) / 100, """" ) ) )"),"")
A5: ISENEBUAI | B5: =IFERROR(__xludf.DUMMYFUNCTION("""COMPUTED_VALUE"""),"PAPUA BARAT") -> PAPUA BARAT | C5: =IFERROR(__xludf.DUMMYFUNCTION("""COMPUTED_VALUE"""),"JS31") -> JS31 | D5: Talis5 Full | E5: 45626 | G5: SNMP sudah up (Done replace ehub) | H5: =AVERAGE(J5:AN5) -> 0.99900429 | I5: =IF(H5<75%, "Potensi SP", "") | J5: =IFERROR(__xludf.DUMMYFUNCTION("""COMPUTED_VALUE"""),1.0) -> 1 | K5: =IFERROR(__xludf.DUMMYFUNCTION("""COMPUTED_VALUE"""),1.0) -> 1 | L5: =IFERROR(__xludf.DUMMYFUNCTION("""COMPUTED_VALUE"""),0.99651) -> 0.99651 | M5: =IFERROR(__xludf.DUMMYFUNCTION("""COMPUTED_VALUE"""),1.0) -> 1 | N5: =IFERROR(__xludf.DUMMYFUNCTION("""COMPUTED_VALUE"""),1.0) -> 1 | O5: =IFERROR(__xludf.DUMMYFUNCTION("""COMPUTED_VALUE"""),1.0) -> 1 | P5: =IFERROR(__xludf.DUMMYFUNCTION("""COMPUTED_VALUE"""),0.99652) -> 0.99652 | Q5: =IFERROR(__xludf.DUMMYFUNCTION("""COMPUTED_VALUE"""),"") | R5: =IFERROR(__xludf.DUMMYFUNCTION("""COMPUTED_VALUE"""),"") | S5: =IFERROR(__xludf.DUMMYFUNCTION("""COMPUTED_VALUE"""),"") | T5: =IFERROR(__xludf.DUMMYFUNCTION("""COMPUTED_VALUE"""),"") | U5: =IFERROR(__xludf.DUMMYFUNCTION("""COMPUTED_VALUE"""),"") | V5: =IFERROR(__xludf.DUMMYFUNCTION("""COMPUTED_VALUE"""),"") | W5: =IFERROR(__xludf.DUMMYFUNCTION("""COMPUTED_VALUE"""),"") | X5: =IFERROR(__xludf.DUMMYFUNCTION("""COMPUTED_VALUE"""),"") | ... AN5: =IFERROR(__xludf.DUMMYFUNCTION("""COMPUTED_VALUE"""),"")
A6: BOHA | B6: =IFERROR(__xludf.DUMMYFUNCTION("""COMPUTED_VALUE"""),"PAPUA SELATAN") -> PAPUA SELATAN | C6: =IFERROR(__xludf.DUMMYFUNCTION("""COMPUTED_VALUE"""),"JS01") -> JS01 | D6: Talis5 Mix | E6: 45974 | G6: SOMO POWER , Vsat sudah up, SNMP problem. done revit tgl 13-nov-25 site up snmp sudah up | H6: =AVERAGE(J6:AN6) -> 1 | I6: =IF(H6<75%, "Potensi SP", "") | J6: =IFERROR(__xludf.DUMMYFUNCTION("""COMPUTED_VALUE"""),1.0) -> 1 | K6: =IFERROR(__xludf.DUMMYFUNCTION("""COMPUTED_VALUE"""),1.0) -> 1 | L6: =IFERROR(__xludf.DUMMYFUNCTION("""COMPUTED_VALUE"""),1.0) -> 1 | M6: =IFERROR(__xludf.DUMMYFUNCTION("""COMPUTED_VALUE"""),1.0) -> 1 | N6: =IFERROR(__xludf.DUMMYFUNCTION("""COMPUTED_VALUE"""),1.0) -> 1 | O6: =IFERROR(__xludf.DUMMYFUNCTION("""COMPUTED_VALUE"""),1.0) -> 1 | P6: =IFERROR(__xludf.DUMMYFUNCTION("""COMPUTED_VALUE"""),1.0) -> 1 | Q6: =IFERROR(__xludf.DUMMYFUNCTION("""COMPUTED_VALUE"""),"") | R6: =IFERROR(__xludf.DUMMYFUNCTION("""COMPUTED_VALUE"""),"") | S6: =IFERROR(__xludf.DUMMYFUNCTION("""COMPUTED_VALUE"""),"") | T6: =IFERROR(__xludf.DUMMYFUNCTION("""COMPUTED_VALUE"""),"") | U6: =IFERROR(__xludf.DUMMYFUNCTION("""COMPUTED_VALUE"""),"") | V6: =IFERROR(__xludf.DUMMYFUNCTION("""COMPUTED_VALUE"""),"") | W6: =IFERROR(__xludf.DUMMYFUNCTION("""COMPUTED_VALUE"""),"") | X6: =IFERROR(__xludf.DUMMYFUNCTION("""COMPUTED_VALUE"""),"") | ... AN6: =IFERROR(__xludf.DUMMYFUNCTION("""COMPUTED_VALUE"""),"")
A7: KOBROR | B7: =IFERROR(__xludf.DUMMYFUNCTION("""COMPUTED_VALUE"""),"MALUKU") -> MALUKU | C7: =IFERROR(__xludf.DUMMYFUNCTION("""COMPUTED_VALUE"""),"JS33") -> JS33 | D7: Talis5 Full | E7: 45936 | G7: Done revit tgl 6/10/25 | H7: =AVERAGE(J7:AN7) -> 0.99801714 | I7: =IF(H7<75%, "Potensi SP", "") | J7: =IFERROR(__xludf.DUMMYFUNCTION("""COMPUTED_VALUE"""),1.0) -> 1 | K7: =IFERROR(__xludf.DUMMYFUNCTION("""COMPUTED_VALUE"""),1.0) -> 1 | L7: =IFERROR(__xludf.DUMMYFUNCTION("""COMPUTED_VALUE"""),0.98612) -> 0.98612 | M7: =IFERROR(__xludf.DUMMYFUNCTION("""COMPUTED_VALUE"""),1.0) -> 1 | N7: =IFERROR(__xludf.DUMMYFUNCTION("""COMPUTED_VALUE"""),1.0) -> 1 | O7: =IFERROR(__xludf.DUMMYFUNCTION("""COMPUTED_VALUE"""),1.0) -> 1 | P7: =IFERROR(__xludf.DUMMYFUNCTION("""COMPUTED_VALUE"""),1.0) -> 1 | Q7: =IFERROR(__xludf.DUMMYFUNCTION("""COMPUTED_VALUE"""),"") | R7: =IFERROR(__xludf.DUMMYFUNCTION("""COMPUTED_VALUE"""),"") | S7: =IFERROR(__xludf.DUMMYFUNCTION("""COMPUTED_VALUE"""),"") | T7: =IFERROR(__xludf.DUMMYFUNCTION("""COMPUTED_VALUE"""),"") | U7: =IFERROR(__xludf.DUMMYFUNCTION("""COMPUTED_VALUE"""),"") | V7: =IFERROR(__xludf.DUMMYFUNCTION("""COMPUTED_VALUE"""),"") | W7: =IFERROR(__xludf.DUMMYFUNCTION("""COMPUTED_VALUE"""),"") | X7: =IFERROR(__xludf.DUMMYFUNCTION("""COMPUTED_VALUE"""),"") | ... AN7: =IFERROR(__xludf.DUMMYFUNCTION("""COMPUTED_VALUE"""),"")
A8: YABORE | B8: =IFERROR(__xludf.DUMMYFUNCTION("""COMPUTED_VALUE"""),"PAPUA BARAT") -> PAPUA BARAT | C8: =IFERROR(__xludf.DUMMYFUNCTION("""COMPUTED_VALUE"""),"JS17") -> JS17 | D8: Talis5 Mix | E8: 45936 | F8: VSAT | G8: VSAT masih down , Done revit tgl 6/10/25 | H8: =AVERAGE(J8:AN8) -> 0 | I8: =IF(H8<75%, "Potensi SP", "") -> Potensi SP | J8: =IFERROR(__xludf.DUMMYFUNCTION("""COMPUTED_VALUE"""),0.0) -> 0 | K8: =IFERROR(__xludf.DUMMYFUNCTION("""COMPUTED_VALUE"""),0.0) -> 0 | L8: =IFERROR(__xludf.DUMMYFUNCTION("""COMPUTED_VALUE"""),0.0) -> 0 | M8: =IFERROR(__xludf.DUMMYFUNCTION("""COMPUTED_VALUE"""),0.0) -> 0 | N8: =IFERROR(__xludf.DUMMYFUNCTION("""COMPUTED_VALUE"""),0.0) -> 0 | O8: =IFERROR(__xludf.DUMMYFUNCTION("""COMPUTED_VALUE"""),0.0) -> 0 | P8: =IFERROR(__xludf.DUMMYFUNCTION("""COMPUTED_VALUE"""),0.0) -> 0 | Q8: =IFERROR(__xludf.DUMMYFUNCTION("""COMPUTED_VALUE"""),"") | R8: =IFERROR(__xludf.DUMMYFUNCTION("""COMPUTED_VALUE"""),"") | S8: =IFERROR(__xludf.DUMMYFUNCTION("""COMPUTED_VALUE"""),"") | T8: =IFERROR(__xludf.DUMMYFUNCTION("""COMPUTED_VALUE"""),"") | U8: =IFERROR(__xludf.DUMMYFUNCTION("""COMPUTED_VALUE"""),"") | V8: =IFERROR(__xludf.DUMMYFUNCTION("""COMPUTED_VALUE"""),"") | W8: =IFERROR(__xludf.DUMMYFUNCTION("""COMPUTED_VALUE"""),"") | X8: =IFERROR(__xludf.DUMMYFUNCTION("""COMPUTED_VALUE"""),"") | ... AN8: =IFERROR(__xludf.DUMMYFUNCTION("""COMPUTED_VALUE"""),"")
A9: INYORA | B9: =IFERROR(__xludf.DUMMYFUNCTION("""COMPUTED_VALUE"""),"PAPUA BARAT") -> PAPUA BARAT | C9: =IFERROR(__xludf.DUMMYFUNCTION("""COMPUTED_VALUE"""),"JS19") -> JS19 | D9: JS PRO | F9: VSAT | G9: VSAT masih down | H9: =AVERAGE(J9:AN9) -> 0 | I9: =IF(H9<75%, "Potensi SP", "") -> Potensi SP | J9: =IFERROR(__xludf.DUMMYFUNCTION("""COMPUTED_VALUE"""),0.0) -> 0 | K9: =IFERROR(__xludf.DUMMYFUNCTION("""COMPUTED_VALUE"""),0.0) -> 0 | L9: =IFERROR(__xludf.DUMMYFUNCTION("""COMPUTED_VALUE"""),0.0) -> 0 | M9: =IFERROR(__xludf.DUMMYFUNCTION("""COMPUTED_VALUE"""),0.0) -> 0 | N9: =IFERROR(__xludf.DUMMYFUNCTION("""COMPUTED_VALUE"""),0.0) -> 0 | O9: =IFERROR(__xludf.DUMMYFUNCTION("""COMPUTED_VALUE"""),0.0) -> 0 | P9: =IFERROR(__xludf.DUMMYFUNCTION("""COMPUTED_VALUE"""),0.0) -> 0 | Q9: =IFERROR(__xludf.DUMMYFUNCTION("""COMPUTED_VALUE"""),"") | R9: =IFERROR(__xludf.DUMMYFUNCTION("""COMPUTED_VALUE"""),"") | S9: =IFERROR(__xludf.DUMMYFUNCTION("""COMPUTED_VALUE"""),"") | T9: =IFERROR(__xludf.DUMMYFUNCTION("""COMPUTED_VALUE"""),"") | U9: =IFERROR(__xludf.DUMMYFUNCTION("""COMPUTED_VALUE"""),"") | V9: =IFERROR(__xludf.DUMMYFUNCTION("""COMPUTED_VALUE"""),"") | W9: =IFERROR(__xludf.DUMMYFUNCTION("""COMPUTED_VALUE"""),"") | X9: =IFERROR(__xludf.DUMMYFUNCTION("""COMPUTED_VALUE"""),"") | ... AN9: =IFERROR(__xludf.DUMMYFUNCTION("""COMPUTED_VALUE"""),"")
A10: SUMAE | B10: =IFERROR(__xludf.DUMMYFUNCTION("""COMPUTED_VALUE"""),"MALUKU UTARA") -> MALUKU UTARA | C10: =IFERROR(__xludf.DUMMYFUNCTION("""COMPUTED_VALUE"""),"JS12") -> JS12 | D10: JS PRO | G10: Vsat sudah up | H10: =AVERAGE(J10:AN10) -> 0.99851143 | I10: =IF(H10<75%, "Potensi SP", "") | J10: =IFERROR(__xludf.DUMMYFUNCTION("""COMPUTED_VALUE"""),1.0) -> 1 | K10: =IFERROR(__xludf.DUMMYFUNCTION("""COMPUTED_VALUE"""),1.0) -> 1 | L10: =IFERROR(__xludf.DUMMYFUNCTION("""COMPUTED_VALUE"""),0.98958) -> 0.98958 | M10: =IFERROR(__xludf.DUMMYFUNCTION("""COMPUTED_VALUE"""),1.0) -> 1 | N10: =IFERROR(__xludf.DUMMYFUNCTION("""COMPUTED_VALUE"""),1.0) -> 1 | O10: =IFERROR(__xludf.DUMMYFUNCTION("""COMPUTED_VALUE"""),1.0) -> 1 | P10: =IFERROR(__xludf.DUMMYFUNCTION("""COMPUTED_VALUE"""),1.0) -> 1 | Q10: =IFERROR(__xludf.DUMMYFUNCTION("""COMPUTED_VALUE"""),"") | R10: =IFERROR(__xludf.DUMMYFUNCTION("""COMPUTED_VALUE"""),"") | S10: =IFERROR(__xludf.DUMMYFUNCTION("""COMPUTED_VALUE"""),"") | T10: =IFERROR(__xludf.DUMMYFUNCTION("""COMPUTED_VALUE"""),"") | U10: =IFERROR(__xludf.DUMMYFUNCTION("""COMPUTED_VALUE"""),"") | V10: =IFERROR(__xludf.DUMMYFUNCTION("""COMPUTED_VALUE"""),"") | W10: =IFERROR(__xludf.DUMMYFUNCTION("""COMPUTED_VALUE"""),"") | X10: =IFERROR(__xludf.DUMMYFUNCTION("""COMPUTED_VALUE"""),"") | ... AN10: =IFERROR(__xludf.DUMMYFUNCTION("""COMPUTED_VALUE"""),"")
A11: TABANGAME | B11: =IFERROR(__xludf.DUMMYFUNCTION("""COMPUTED_VALUE"""),"MALUKU UTARA") -> MALUKU UTARA | C11: =IFERROR(__xludf.DUMMYFUNCTION("""COMPUTED_VALUE"""),"JS13") -> JS13 | D11: Talis5 Mix (Migrasi pln) | E11: 45973 | G11: SOMO BTS , power up down done revit tgl 12-nov-25 | H11: =AVERAGE(J11:AN11) -> 1 | I11: =IF(H11<75%, "Potensi SP", "") | J11: =IFERROR(__xludf.DUMMYFUNCTION("""COMPUTED_VALUE"""),1.0) -> 1 | K11: =IFERROR(__xludf.DUMMYFUNCTION("""COMPUTED_VALUE"""),1.0) -> 1 | L11: =IFERROR(__xludf.DUMMYFUNCTION("""COMPUTED_VALUE"""),1.0) -> 1 | M11: =IFERROR(__xludf.DUMMYFUNCTION("""COMPUTED_VALUE"""),1.0) -> 1 | N11: =IFERROR(__xludf.DUMMYFUNCTION("""COMPUTED_VALUE"""),1.0) -> 1 | O11: =IFERROR(__xludf.DUMMYFUNCTION("""COMPUTED_VALUE"""),1.0) -> 1 | P11: =IFERROR(__xludf.DUMMYFUNCTION("""COMPUTED_VALUE"""),1.0) -> 1 | Q11: =IFERROR(__xludf.DUMMYFUNCTION("""COMPUTED_VALUE"""),"") | R11: =IFERROR(__xludf.DUMMYFUNCTION("""COMPUTED_VALUE"""),"") | S11: =IFERROR(__xludf.DUMMYFUNCTION("""COMPUTED_VALUE"""),"") | T11: =IFERROR(__xludf.DUMMYFUNCTION("""COMPUTED_VALUE"""),"") | U11: =IFERROR(__xludf.DUMMYFUNCTION("""COMPUTED_VALUE"""),"") | V11: =IFERROR(__xludf.DUMMYFUNCTION("""COMPUTED_VALUE"""),"") | W11: =IFERROR(__xludf.DUMMYFUNCTION("""COMPUTED_VALUE"""),"") | X11: =IFERROR(__xludf.DUMMYFUNCTION("""COMPUTED_VALUE"""),"") | ... AN11: =IFERROR(__xludf.DUMMYFUNCTION("""COMPUTED_VALUE"""),"")
A12: HUKUKECIL | B12: =IFERROR(__xludf.DUMMYFUNCTION("""COMPUTED_VALUE"""),"MALUKU") -> MALUKU | C12: =IFERROR(__xludf.DUMMYFUNCTION("""COMPUTED_VALUE"""),"JS43") -> JS43 | D12: Talis5 Mix | E12: 45968 | F12: VSAT | G12: vsat sudh up | H12: =AVERAGE(J12:AN12) -> 0.45450286 | I12: =IF(H12<75%, "Potensi SP", "") -> Potensi SP | J12: =IFERROR(__xludf.DUMMYFUNCTION("""COMPUTED_VALUE"""),0.0) -> 0 | K12: =IFERROR(__xludf.DUMMYFUNCTION("""COMPUTED_VALUE"""),0.0) -> 0 | L12: =IFERROR(__xludf.DUMMYFUNCTION("""COMPUTED_VALUE"""),0.58431) -> 0.58431 | M12: =IFERROR(__xludf.DUMMYFUNCTION("""COMPUTED_VALUE"""),0.47125) -> 0.47125 | N12: =IFERROR(__xludf.DUMMYFUNCTION("""COMPUTED_VALUE"""),0.25791000000000003) -> 0.25791 | O12: =IFERROR(__xludf.DUMMYFUNCTION("""COMPUTED_VALUE"""),0.8680500000000001) -> 0.86805 | P12: =IFERROR(__xludf.DUMMYFUNCTION("""COMPUTED_VALUE"""),1.0) -> 1 | Q12: =IFERROR(__xludf.DUMMYFUNCTION("""COMPUTED_VALUE"""),"") | R12: =IFERROR(__xludf.DUMMYFUNCTION("""COMPUTED_VALUE"""),"") | S12: =IFERROR(__xludf.DUMMYFUNCTION("""COMPUTED_VALUE"""),"") | T12: =IFERROR(__xludf.DUMMYFUNCTION("""COMPUTED_VALUE"""),"") | U12: =IFERROR(__xludf.DUMMYFUNCTION("""COMPUTED_VALUE"""),"") | V12: =IFERROR(__xludf.DUMMYFUNCTION("""COMPUTED_VALUE"""),"") | W12: =IFERROR(__xludf.DUMMYFUNCTION("""COMPUTED_VALUE"""),"") | X12: =IFERROR(__xludf.DUMMYFUNCTION("""COMPUTED_VALUE"""),"") | ... AN12: =IFERROR(__xludf.DUMMYFUNCTION("""COMPUTED_VALUE"""),"")
A13: RENIS | B13: =IFERROR(__xludf.DUMMYFUNCTION("""COMPUTED_VALUE"""),"PAPUA BARAT") -> PAPUA BARAT | C13: =IFERROR(__xludf.DUMMYFUNCTION("""COMPUTED_VALUE"""),"JS61") -> JS61 | D13: JS PRO | F13: VSAT | G13: Vsat up down sudah stabil | H13: =AVERAGE(J13:AN13) -> 0.81051143 | I13: =IF(H13<75%, "Potensi SP", "") | J13: =IFERROR(__xludf.DUMMYFUNCTION("""COMPUTED_VALUE"""),0.6011099999999999) -> 0.60111 | K13: =IFERROR(__xludf.DUMMYFUNCTION("""COMPUTED_VALUE"""),0.78083) -> 0.78083 | L13: =IFERROR(__xludf.DUMMYFUNCTION("""COMPUTED_VALUE"""),0.79208) -> 0.79208 | M13: =IFERROR(__xludf.DUMMYFUNCTION("""COMPUTED_VALUE"""),0.49956) -> 0.49956 | N13: =IFERROR(__xludf.DUMMYFUNCTION("""COMPUTED_VALUE"""),1.0) -> 1 | O13: =IFERROR(__xludf.DUMMYFUNCTION("""COMPUTED_VALUE"""),1.0) -> 1 | P13: =IFERROR(__xludf.DUMMYFUNCTION("""COMPUTED_VALUE"""),1.0) -> 1 | Q13: =IFERROR(__xludf.DUMMYFUNCTION("""COMPUTED_VALUE"""),"") | R13: =IFERROR(__xludf.DUMMYFUNCTION("""COMPUTED_VALUE"""),"") | S13: =IFERROR(__xludf.DUMMYFUNCTION("""COMPUTED_VALUE"""),"") | T13: =IFERROR(__xludf.DUMMYFUNCTION("""COMPUTED_VALUE"""),"") | U13: =IFERROR(__xludf.DUMMYFUNCTION("""COMPUTED_VALUE"""),"") | V13: =IFERROR(__xludf.DUMMYFUNCTION("""COMPUTED_VALUE"""),"") | W13: =IFERROR(__xludf.DUMMYFUNCTION("""COMPUTED_VALUE"""),"") | X13: =IFERROR(__xludf.DUMMYFUNCTION("""COMPUTED_VALUE"""),"") | ... AN13: =IFERROR(__xludf.DUMMYFUNCTION("""COMPUTED_VALUE"""),"")
A14: ELIASA | B14: =IFERROR(__xludf.DUMMYFUNCTION("""COMPUTED_VALUE"""),"MALUKU") -> MALUKU | C14: =IFERROR(__xludf.DUMMYFUNCTION("""COMPUTED_VALUE"""),"JS34") -> JS34 | D14: Talis5 Mix | E14: 04 March 2025 | G14: SNMP sudah up | H14: =AVERAGE(J14:AN14) -> 1 | I14: =IF(H14<75%, "Potensi SP", "") | J14: =IFERROR(__xludf.DUMMYFUNCTION("""COMPUTED_VALUE"""),1.0) -> 1 | K14: =IFERROR(__xludf.DUMMYFUNCTION("""COMPUTED_VALUE"""),1.0) -> 1 | L14: =IFERROR(__xludf.DUMMYFUNCTION("""COMPUTED_VALUE"""),1.0) -> 1 | M14: =IFERROR(__xludf.DUMMYFUNCTION("""COMPUTED_VALUE"""),1.0) -> 1 | N14: =IFERROR(__xludf.DUMMYFUNCTION("""COMPUTED_VALUE"""),1.0) -> 1 | O14: =IFERROR(__xludf.DUMMYFUNCTION("""COMPUTED_VALUE"""),1.0) -> 1 | P14: =IFERROR(__xludf.DUMMYFUNCTION("""COMPUTED_VALUE"""),1.0) -> 1 | Q14: =IFERROR(__xludf.DUMMYFUNCTION("""COMPUTED_VALUE"""),"") | R14: =IFERROR(__xludf.DUMMYFUNCTION("""COMPUTED_VALUE"""),"") | S14: =IFERROR(__xludf.DUMMYFUNCTION("""COMPUTED_VALUE"""),"") | T14: =IFERROR(__xludf.DUMMYFUNCTION("""COMPUTED_VALUE"""),"") | U14: =IFERROR(__xludf.DUMMYFUNCTION("""COMPUTED_VALUE"""),"") | V14: =IFERROR(__xludf.DUMMYFUNCTION("""COMPUTED_VALUE"""),"") | W14: =IFERROR(__xludf.DUMMYFUNCTION("""COMPUTED_VALUE"""),"") | X14: =IFERROR(__xludf.DUMMYFUNCTION("""COMPUTED_VALUE"""),"") | ... AN14: =IFERROR(__xludf.DUMMYFUNCTION("""COMPUTED_VALUE"""),"")
A15: HONITETU | B15: =IFERROR(__xludf.DUMMYFUNCTION("""COMPUTED_VALUE"""),"MALUKU") -> MALUKU | C15: =IFERROR(__xludf.DUMMYFUNCTION("""COMPUTED_VALUE"""),"JS42") -> JS42 | D15: Talis5 Mix (Migrasi pln) | E15: 45960 | G15: SNMP sudah up | H15: =AVERAGE(J15:AN15) -> 1 | I15: =IF(H15<75%, "Potensi SP", "") | J15: =IFERROR(__xludf.DUMMYFUNCTION("""COMPUTED_VALUE"""),1.0) -> 1 | K15: =IFERROR(__xludf.DUMMYFUNCTION("""COMPUTED_VALUE"""),1.0) -> 1 | L15: =IFERROR(__xludf.DUMMYFUNCTION("""COMPUTED_VALUE"""),1.0) -> 1 | M15: =IFERROR(__xludf.DUMMYFUNCTION("""COMPUTED_VALUE"""),1.0) -> 1 | N15: =IFERROR(__xludf.DUMMYFUNCTION("""COMPUTED_VALUE"""),1.0) -> 1 | O15: =IFERROR(__xludf.DUMMYFUNCTION("""COMPUTED_VALUE"""),1.0) -> 1 | P15: =IFERROR(__xludf.DUMMYFUNCTION("""COMPUTED_VALUE"""),1.0) -> 1 | Q15: =IFERROR(__xludf.DUMMYFUNCTION("""COMPUTED_VALUE"""),"") | R15: =IFERROR(__xludf.DUMMYFUNCTION("""COMPUTED_VALUE"""),"") | S15: =IFERROR(__xludf.DUMMYFUNCTION("""COMPUTED_VALUE"""),"") | T15: =IFERROR(__xludf.DUMMYFUNCTION("""COMPUTED_VALUE"""),"") | U15: =IFERROR(__xludf.DUMMYFUNCTION("""COMPUTED_VALUE"""),"") | V15: =IFERROR(__xludf.DUMMYFUNCTION("""COMPUTED_VALUE"""),"") | W15: =IFERROR(__xludf.DUMMYFUNCTION("""COMPUTED_VALUE"""),"") | X15: =IFERROR(__xludf.DUMMYFUNCTION("""COMPUTED_VALUE"""),"") | ... AN15: =IFERROR(__xludf.DUMMYFUNCTION("""COMPUTED_VALUE"""),"")
A16: AISA | B16: =IFERROR(__xludf.DUMMYFUNCTION("""COMPUTED_VALUE"""),"PAPUA BARAT") -> PAPUA BARAT | C16: =IFERROR(__xludf.DUMMYFUNCTION("""COMPUTED_VALUE"""),"JS69") -> JS69 | D16: JS PRO | G16: Vsat sudah up | H16: =AVERAGE(J16:AN16) -> 0.99851143 | J16: =IFERROR(__xludf.DUMMYFUNCTION("""COMPUTED_VALUE"""),0.99653) -> 0.99653 | K16: =IFERROR(__xludf.DUMMYFUNCTION("""COMPUTED_VALUE"""),1.0) -> 1 | L16: =IFERROR(__xludf.DUMMYFUNCTION("""COMPUTED_VALUE"""),1.0) -> 1 | M16: =IFERROR(__xludf.DUMMYFUNCTION("""COMPUTED_VALUE"""),1.0) -> 1 | N16: =IFERROR(__xludf.DUMMYFUNCTION("""COMPUTED_VALUE"""),0.9930500000000001) -> 0.99305 | O16: =IFERROR(__xludf.DUMMYFUNCTION("""COMPUTED_VALUE"""),1.0) -> 1 | P16: =IFERROR(__xludf.DUMMYFUNCTION("""COMPUTED_VALUE"""),1.0) -> 1 | Q16: =IFERROR(__xludf.DUMMYFUNCTION("""COMPUTED_VALUE"""),"") | R16: =IFERROR(__xludf.DUMMYFUNCTION("""COMPUTED_VALUE"""),"") | S16: =IFERROR(__xludf.DUMMYFUNCTION("""COMPUTED_VALUE"""),"") | T16: =IFERROR(__xludf.DUMMYFUNCTION("""COMPUTED_VALUE"""),"") | U16: =IFERROR(__xludf.DUMMYFUNCTION("""COMPUTED_VALUE"""),"") | V16: =IFERROR(__xludf.DUMMYFUNCTION("""COMPUTED_VALUE"""),"") | W16: =IFERROR(__xludf.DUMMYFUNCTION("""COMPUTED_VALUE"""),"") | X16: =IFERROR(__xludf.DUMMYFUNCTION("""COMPUTED_VALUE"""),"") | ... AN16: =IFERROR(__xludf.DUMMYFUNCTION("""COMPUTED_VALUE"""),"")
A17: KOREWATARA | B17: =IFERROR(__xludf.DUMMYFUNCTION("""COMPUTED_VALUE"""),"PAPUA BARAT") -> PAPUA BARAT | C17: =IFERROR(__xludf.DUMMYFUNCTION("""COMPUTED_VALUE"""),"JS87") -> JS87 | D17: JS PRO | G17: SNMP sudah up | H17: =AVERAGE(J17:AN17) -> 0.99900571 | I17: =IF(H17<75%, "Potensi SP", "") | J17: =IFERROR(__xludf.DUMMYFUNCTION("""COMPUTED_VALUE"""),1.0) -> 1 | K17: =IFERROR(__xludf.DUMMYFUNCTION("""COMPUTED_VALUE"""),0.99652) -> 0.99652 | L17: =IFERROR(__xludf.DUMMYFUNCTION("""COMPUTED_VALUE"""),1.0) -> 1 | M17: =IFERROR(__xludf.DUMMYFUNCTION("""COMPUTED_VALUE"""),1.0) -> 1 | N17: =IFERROR(__xludf.DUMMYFUNCTION("""COMPUTED_VALUE"""),1.0) -> 1 | O17: =IFERROR(__xludf.DUMMYFUNCTION("""COMPUTED_VALUE"""),1.0) -> 1 | P17: =IFERROR(__xludf.DUMMYFUNCTION("""COMPUTED_VALUE"""),0.99652) -> 0.99652 | Q17: =IFERROR(__xludf.DUMMYFUNCTION("""COMPUTED_VALUE"""),"") | R17: =IFERROR(__xludf.DUMMYFUNCTION("""COMPUTED_VALUE"""),"") | S17: =IFERROR(__xludf.DUMMYFUNCTION("""COMPUTED_VALUE"""),"") | T17: =IFERROR(__xludf.DUMMYFUNCTION("""COMPUTED_VALUE"""),"") | U17: =IFERROR(__xludf.DUMMYFUNCTION("""COMPUTED_VALUE"""),"") | V17: =IFERROR(__xludf.DUMMYFUNCTION("""COMPUTED_VALUE"""),"") | W17: =IFERROR(__xludf.DUMMYFUNCTION("""COMPUTED_VALUE"""),"") | X17: =IFERROR(__xludf.DUMMYFUNCTION("""COMPUTED_VALUE"""),"") | ... AN17: =IFERROR(__xludf.DUMMYFUNCTION("""COMPUTED_VALUE"""),"")
A18: OCIMALOLEO | B18: =IFERROR(__xludf.DUMMYFUNCTION("""COMPUTED_VALUE"""),"MALUKU UTARA") -> MALUKU UTARA | C18: =IFERROR(__xludf.DUMMYFUNCTION("""COMPUTED_VALUE"""),"JS127") -> JS127 | D18: JS PRO | F18: VSAT | G18: vsat sudah up | H18: =AVERAGE(J18:AN18) -> 0.88194143 | I18: =IF(H18<75%, "Potensi SP", "") | J18: =IFERROR(__xludf.DUMMYFUNCTION("""COMPUTED_VALUE"""),1.0) -> 1 | K18: =IFERROR(__xludf.DUMMYFUNCTION("""COMPUTED_VALUE"""),1.0) -> 1 | L18: =IFERROR(__xludf.DUMMYFUNCTION("""COMPUTED_VALUE"""),1.0) -> 1 | M18: =IFERROR(__xludf.DUMMYFUNCTION("""COMPUTED_VALUE"""),0.6556399999999999) -> 0.65564 | N18: =IFERROR(__xludf.DUMMYFUNCTION("""COMPUTED_VALUE"""),0.51795) -> 0.51795 | O18: =IFERROR(__xludf.DUMMYFUNCTION("""COMPUTED_VALUE"""),1.0) -> 1 | P18: =IFERROR(__xludf.DUMMYFUNCTION("""COMPUTED_VALUE"""),1.0) -> 1 | Q18: =IFERROR(__xludf.DUMMYFUNCTION("""COMPUTED_VALUE"""),"") | R18: =IFERROR(__xludf.DUMMYFUNCTION("""COMPUTED_VALUE"""),"") | S18: =IFERROR(__xludf.DUMMYFUNCTION("""COMPUTED_VALUE"""),"") | T18: =IFERROR(__xludf.DUMMYFUNCTION("""COMPUTED_VALUE"""),"") | U18: =IFERROR(__xludf.DUMMYFUNCTION("""COMPUTED_VALUE"""),"") | V18: =IFERROR(__xludf.DUMMYFUNCTION("""COMPUTED_VALUE"""),"") | W18: =IFERROR(__xludf.DUMMYFUNCTION("""COMPUTED_VALUE"""),"") | X18: =IFERROR(__xludf.DUMMYFUNCTION("""COMPUTED_VALUE"""),"") | ... AN18: =IFERROR(__xludf.DUMMYFUNCTION("""COMPUTED_VALUE"""),"")
A19: WAYATIM | B19: =IFERROR(__xludf.DUMMYFUNCTION("""COMPUTED_VALUE"""),"MALUKU UTARA") -> MALUKU UTARA | C19: =IFERROR(__xludf.DUMMYFUNCTION("""COMPUTED_VALUE"""),"JS10") -> JS10 | D19: JS PRO | G19: Sudah up | H19: =AVERAGE(J19:AN19) -> 1 | I19: =IF(H19<75%, "Potensi SP", "") | J19: =IFERROR(__xludf.DUMMYFUNCTION("""COMPUTED_VALUE"""),1.0) -> 1 | K19: =IFERROR(__xludf.DUMMYFUNCTION("""COMPUTED_VALUE"""),1.0) -> 1 | L19: =IFERROR(__xludf.DUMMYFUNCTION("""COMPUTED_VALUE"""),1.0) -> 1 | M19: =IFERROR(__xludf.DUMMYFUNCTION("""COMPUTED_VALUE"""),1.0) -> 1 | N19: =IFERROR(__xludf.DUMMYFUNCTION("""COMPUTED_VALUE"""),1.0) -> 1 | O19: =IFERROR(__xludf.DUMMYFUNCTION("""COMPUTED_VALUE"""),1.0) -> 1 | P19: =IFERROR(__xludf.DUMMYFUNCTION("""COMPUTED_VALUE"""),1.0) -> 1 | Q19: =IFERROR(__xludf.DUMMYFUNCTION("""COMPUTED_VALUE"""),"") | R19: =IFERROR(__xludf.DUMMYFUNCTION("""COMPUTED_VALUE"""),"") | S19: =IFERROR(__xludf.DUMMYFUNCTION("""COMPUTED_VALUE"""),"") | T19: =IFERROR(__xludf.DUMMYFUNCTION("""COMPUTED_VALUE"""),"") | U19: =IFERROR(__xludf.DUMMYFUNCTION("""COMPUTED_VALUE"""),"") | V19: =IFERROR(__xludf.DUMMYFUNCTION("""COMPUTED_VALUE"""),"") | W19: =IFERROR(__xludf.DUMMYFUNCTION("""COMPUTED_VALUE"""),"") | X19: =IFERROR(__xludf.DUMMYFUNCTION("""COMPUTED_VALUE"""),"") | ... AN19: =IFERROR(__xludf.DUMMYFUNCTION("""COMPUTED_VALUE"""),"")
A20: WARLOI | B20: =IFERROR(__xludf.DUMMYFUNCTION("""COMPUTED_VALUE"""),"MALUKU") -> MALUKU | C20: =IFERROR(__xludf.DUMMYFUNCTION("""COMPUTED_VALUE"""),"JS28") -> JS28 | D20: JS PRO | G20: SNMP sudah up | H20: =AVERAGE(J20:AN20) -> 1 | I20: =IF(H20<75%, "Potensi SP", "") | J20: =IFERROR(__xludf.DUMMYFUNCTION("""COMPUTED_VALUE"""),1.0) -> 1 | K20: =IFERROR(__xludf.DUMMYFUNCTION("""COMPUTED_VALUE"""),1.0) -> 1 | L20: =IFERROR(__xludf.DUMMYFUNCTION("""COMPUTED_VALUE"""),1.0) -> 1 | M20: =IFERROR(__xludf.DUMMYFUNCTION("""COMPUTED_VALUE"""),1.0) -> 1 | N20: =IFERROR(__xludf.DUMMYFUNCTION("""COMPUTED_VALUE"""),1.0) -> 1 | O20: =IFERROR(__xludf.DUMMYFUNCTION("""COMPUTED_VALUE"""),1.0) -> 1 | P20: =IFERROR(__xludf.DUMMYFUNCTION("""COMPUTED_VALUE"""),1.0) -> 1 | Q20: =IFERROR(__xludf.DUMMYFUNCTION("""COMPUTED_VALUE"""),"") | R20: =IFERROR(__xludf.DUMMYFUNCTION("""COMPUTED_VALUE"""),"") | S20: =IFERROR(__xludf.DUMMYFUNCTION("""COMPUTED_VALUE"""),"") | T20: =IFERROR(__xludf.DUMMYFUNCTION("""COMPUTED_VALUE"""),"") | U20: =IFERROR(__xludf.DUMMYFUNCTION("""COMPUTED_VALUE"""),"") | V20: =IFERROR(__xludf.DUMMYFUNCTION("""COMPUTED_VALUE"""),"") | W20: =IFERROR(__xludf.DUMMYFUNCTION("""COMPUTED_VALUE"""),"") | X20: =IFERROR(__xludf.DUMMYFUNCTION("""COMPUTED_VALUE"""),"") | ... AN20: =IFERROR(__xludf.DUMMYFUNCTION("""COMPUTED_VALUE"""),"")
A21: RUMOY | B21: =IFERROR(__xludf.DUMMYFUNCTION("""COMPUTED_VALUE"""),"MALUKU") -> MALUKU | C21: =IFERROR(__xludf.DUMMYFUNCTION("""COMPUTED_VALUE"""),"JS97") -> JS97 | D21: Talis5 Full | E21: 12 December 2024 | F21: POWER-Tiket-onprogres | G21: SNMP masih down | H21: =AVERAGE(J21:AN21) -> 0 | I21: =IF(H21<75%, "Potensi SP", "") -> Potensi SP | J21: =IFERROR(__xludf.DUMMYFUNCTION("""COMPUTED_VALUE"""),0.0) -> 0 | K21: =IFERROR(__xludf.DUMMYFUNCTION("""COMPUTED_VALUE"""),0.0) -> 0 | L21: =IFERROR(__xludf.DUMMYFUNCTION("""COMPUTED_VALUE"""),0.0) -> 0 | M21: =IFERROR(__xludf.DUMMYFUNCTION("""COMPUTED_VALUE"""),0.0) -> 0 | N21: =IFERROR(__xludf.DUMMYFUNCTION("""COMPUTED_VALUE"""),0.0) -> 0 | O21: =IFERROR(__xludf.DUMMYFUNCTION("""COMPUTED_VALUE"""),0.0) -> 0 | P21: =IFERROR(__xludf.DUMMYFUNCTION("""COMPUTED_VALUE"""),0.0) -> 0 | Q21: =IFERROR(__xludf.DUMMYFUNCTION("""COMPUTED_VALUE"""),"") | R21: =IFERROR(__xludf.DUMMYFUNCTION("""COMPUTED_VALUE"""),"") | S21: =IFERROR(__xludf.DUMMYFUNCTION("""COMPUTED_VALUE"""),"") | T21: =IFERROR(__xludf.DUMMYFUNCTION("""COMPUTED_VALUE"""),"") | U21: =IFERROR(__xludf.DUMMYFUNCTION("""COMPUTED_VALUE"""),"") | V21: =IFERROR(__xludf.DUMMYFUNCTION("""COMPUTED_VALUE"""),"") | W21: =IFERROR(__xludf.DUMMYFUNCTION("""COMPUTED_VALUE"""),"") | X21: =IFERROR(__xludf.DUMMYFUNCTION("""COMPUTED_VALUE"""),"") | ... AN21: =IFERROR(__xludf.DUMMYFUNCTION("""COMPUTED_VALUE"""),"")
A22: BORI | B22: =IFERROR(__xludf.DUMMYFUNCTION("""COMPUTED_VALUE"""),"PAPUA BARAT") -> PAPUA BARAT | C22: =IFERROR(__xludf.DUMMYFUNCTION("""COMPUTED_VALUE"""),"JS50") -> JS50 | D22: JS PRO | G22: Insiden Power Terbakar (Done donor), site sudah up | H22: =AVERAGE(J22:AN22) -> 0.98065286 | I22: =IF(H22<75%, "Potensi SP", "") | J22: =IFERROR(__xludf.DUMMYFUNCTION("""COMPUTED_VALUE"""),1.0) -> 1 | K22: =IFERROR(__xludf.DUMMYFUNCTION("""COMPUTED_VALUE"""),1.0) -> 1 | L22: =IFERROR(__xludf.DUMMYFUNCTION("""COMPUTED_VALUE"""),0.99652) -> 0.99652 | M22: =IFERROR(__xludf.DUMMYFUNCTION("""COMPUTED_VALUE"""),0.8680500000000001) -> 0.86805 | N22: =IFERROR(__xludf.DUMMYFUNCTION("""COMPUTED_VALUE"""),1.0) -> 1 | O22: =IFERROR(__xludf.DUMMYFUNCTION("""COMPUTED_VALUE"""),1.0) -> 1 | P22: =IFERROR(__xludf.DUMMYFUNCTION("""COMPUTED_VALUE"""),1.0) -> 1 | Q22: =IFERROR(__xludf.DUMMYFUNCTION("""COMPUTED_VALUE"""),"") | R22: =IFERROR(__xludf.DUMMYFUNCTION("""COMPUTED_VALUE"""),"") | S22: =IFERROR(__xludf.DUMMYFUNCTION("""COMPUTED_VALUE"""),"") | T22: =IFERROR(__xludf.DUMMYFUNCTION("""COMPUTED_VALUE"""),"") | U22: =IFERROR(__xludf.DUMMYFUNCTION("""COMPUTED_VALUE"""),"") | V22: =IFERROR(__xludf.DUMMYFUNCTION("""COMPUTED_VALUE"""),"") | W22: =IFERROR(__xludf.DUMMYFUNCTION("""COMPUTED_VALUE"""),"") | X22: =IFERROR(__xludf.DUMMYFUNCTION("""COMPUTED_VALUE"""),"") | ... AN22: =IFERROR(__xludf.DUMMYFUNCTION("""COMPUTED_VALUE"""),"")
A23: MAKARORO | B23: =IFERROR(__xludf.DUMMYFUNCTION("""COMPUTED_VALUE"""),"PAPUA BARAT") -> PAPUA BARAT | C23: =IFERROR(__xludf.DUMMYFUNCTION("""COMPUTED_VALUE"""),"JS76") -> JS76 | D23: Talis5 Full | E23: 15 December 2024 | F23: POWER | G23: SNMP up down | H23: =AVERAGE(J23:AN23) -> 0.75631429 | I23: =IF(H23<75%, "Potensi SP", "") | J23: =IFERROR(__xludf.DUMMYFUNCTION("""COMPUTED_VALUE"""),0.0) -> 0 | K23: =IFERROR(__xludf.DUMMYFUNCTION("""COMPUTED_VALUE"""),0.63798) -> 0.63798 | L23: =IFERROR(__xludf.DUMMYFUNCTION("""COMPUTED_VALUE"""),1.0) -> 1 | M23: =IFERROR(__xludf.DUMMYFUNCTION("""COMPUTED_VALUE"""),0.7569400000000001) -> 0.75694 | N23: =IFERROR(__xludf.DUMMYFUNCTION("""COMPUTED_VALUE"""),0.89928) -> 0.89928 | O23: =IFERROR(__xludf.DUMMYFUNCTION("""COMPUTED_VALUE"""),1.0) -> 1 | P23: =IFERROR(__xludf.DUMMYFUNCTION("""COMPUTED_VALUE"""),1.0) -> 1 | Q23: =IFERROR(__xludf.DUMMYFUNCTION("""COMPUTED_VALUE"""),"") | R23: =IFERROR(__xludf.DUMMYFUNCTION("""COMPUTED_VALUE"""),"") | S23: =IFERROR(__xludf.DUMMYFUNCTION("""COMPUTED_VALUE"""),"") | T23: =IFERROR(__xludf.DUMMYFUNCTION("""COMPUTED_VALUE"""),"") | U23: =IFERROR(__xludf.DUMMYFUNCTION("""COMPUTED_VALUE"""),"") | V23: =IFERROR(__xludf.DUMMYFUNCTION("""COMPUTED_VALUE"""),"") | W23: =IFERROR(__xludf.DUMMYFUNCTION("""COMPUTED_VALUE"""),"") | X23: =IFERROR(__xludf.DUMMYFUNCTION("""COMPUTED_VALUE"""),"") | ... AN23: =IFERROR(__xludf.DUMMYFUNCTION("""COMPUTED_VALUE"""),"")
A24: MAWE | B24: =IFERROR(__xludf.DUMMYFUNCTION("""COMPUTED_VALUE"""),"PAPUA BARAT") -> PAPUA BARAT | C24: =IFERROR(__xludf.DUMMYFUNCTION("""COMPUTED_VALUE"""),"JS53") -> JS53 | D24: JS PRO | H24: =AVERAGE(J24:AN24) -> 0.99950143 | I24: =IF(H24<75%, "Potensi SP", "") | J24: =IFERROR(__xludf.DUMMYFUNCTION("""COMPUTED_VALUE"""),1.0) -> 1 | K24: =IFERROR(__xludf.DUMMYFUNCTION("""COMPUTED_VALUE"""),1.0) -> 1 | L24: =IFERROR(__xludf.DUMMYFUNCTION("""COMPUTED_VALUE"""),1.0) -> 1 | M24: =IFERROR(__xludf.DUMMYFUNCTION("""COMPUTED_VALUE"""),1.0) -> 1 | N24: =IFERROR(__xludf.DUMMYFUNCTION("""COMPUTED_VALUE"""),0.99651) -> 0.99651 | O24: =IFERROR(__xludf.DUMMYFUNCTION("""COMPUTED_VALUE"""),1.0) -> 1 | P24: =IFERROR(__xludf.DUMMYFUNCTION("""COMPUTED_VALUE"""),1.0) -> 1 | Q24: =IFERROR(__xludf.DUMMYFUNCTION("""COMPUTED_VALUE"""),"") | R24: =IFERROR(__xludf.DUMMYFUNCTION("""COMPUTED_VALUE"""),"") | S24: =IFERROR(__xludf.DUMMYFUNCTION("""COMPUTED_VALUE"""),"") | T24: =IFERROR(__xludf.DUMMYFUNCTION("""COMPUTED_VALUE"""),"") | U24: =IFERROR(__xludf.DUMMYFUNCTION("""COMPUTED_VALUE"""),"") | V24: =IFERROR(__xludf.DUMMYFUNCTION("""COMPUTED_VALUE"""),"") | W24: =IFERROR(__xludf.DUMMYFUNCTION("""COMPUTED_VALUE"""),"") | X24: =IFERROR(__xludf.DUMMYFUNCTION("""COMPUTED_VALUE"""),"") | ... AN24: =IFERROR(__xludf.DUMMYFUNCTION("""COMPUTED_VALUE"""),"")
A25: KAMPUNG BARU 1 | B25: =IFERROR(__xludf.DUMMYFUNCTION("""COMPUTED_VALUE"""),"MALUKU UTARA") -> MALUKU UTARA | C25: =IFERROR(__xludf.DUMMYFUNCTION("""COMPUTED_VALUE"""),"JS8") -> JS8 | D25: JS PRO | G25: SNMP sudah UP | H25: =AVERAGE(J25:AN25) -> 0.99900857 | I25: =IF(H25<75%, "Potensi SP", "") | J25: =IFERROR(__xludf.DUMMYFUNCTION("""COMPUTED_VALUE"""),1.0) -> 1 | K25: =IFERROR(__xludf.DUMMYFUNCTION("""COMPUTED_VALUE"""),1.0) -> 1 | L25: =IFERROR(__xludf.DUMMYFUNCTION("""COMPUTED_VALUE"""),1.0) -> 1 | M25: =IFERROR(__xludf.DUMMYFUNCTION("""COMPUTED_VALUE"""),1.0) -> 1 | N25: =IFERROR(__xludf.DUMMYFUNCTION("""COMPUTED_VALUE"""),0.9930599999999999) -> 0.99306 | O25: =IFERROR(__xludf.DUMMYFUNCTION("""COMPUTED_VALUE"""),1.0) -> 1 | P25: =IFERROR(__xludf.DUMMYFUNCTION("""COMPUTED_VALUE"""),1.0) -> 1 | Q25: =IFERROR(__xludf.DUMMYFUNCTION("""COMPUTED_VALUE"""),"") | R25: =IFERROR(__xludf.DUMMYFUNCTION("""COMPUTED_VALUE"""),"") | S25: =IFERROR(__xludf.DUMMYFUNCTION("""COMPUTED_VALUE"""),"") | T25: =IFERROR(__xludf.DUMMYFUNCTION("""COMPUTED_VALUE"""),"") | U25: =IFERROR(__xludf.DUMMYFUNCTION("""COMPUTED_VALUE"""),"") | V25: =IFERROR(__xludf.DUMMYFUNCTION("""COMPUTED_VALUE"""),"") | W25: =IFERROR(__xludf.DUMMYFUNCTION("""COMPUTED_VALUE"""),"") | X25: =IFERROR(__xludf.DUMMYFUNCTION("""COMPUTED_VALUE"""),"") | ... AN25: =IFERROR(__xludf.DUMMYFUNCTION("""COMPUTED_VALUE"""),"")
A26: NIAP | B26: =IFERROR(__xludf.DUMMYFUNCTION("""COMPUTED_VALUE"""),"PAPUA BARAT") -> PAPUA BARAT | C26: =IFERROR(__xludf.DUMMYFUNCTION("""COMPUTED_VALUE"""),"JS26") -> JS26 | D26: Talis5 Full | E26: 04 August 2025 | G26: SNMP sudah UP | H26: =AVERAGE(J26:AN26) -> 1 | I26: =IF(H26<75%, "Potensi SP", "") | J26: =IFERROR(__xludf.DUMMYFUNCTION("""COMPUTED_VALUE"""),1.0) -> 1 | K26: =IFERROR(__xludf.DUMMYFUNCTION("""COMPUTED_VALUE"""),1.0) -> 1 | L26: =IFERROR(__xludf.DUMMYFUNCTION("""COMPUTED_VALUE"""),1.0) -> 1 | M26: =IFERROR(__xludf.DUMMYFUNCTION("""COMPUTED_VALUE"""),1.0) -> 1 | N26: =IFERROR(__xludf.DUMMYFUNCTION("""COMPUTED_VALUE"""),1.0) -> 1 | O26: =IFERROR(__xludf.DUMMYFUNCTION("""COMPUTED_VALUE"""),1.0) -> 1 | P26: =IFERROR(__xludf.DUMMYFUNCTION("""COMPUTED_VALUE"""),1.0) -> 1 | Q26: =IFERROR(__xludf.DUMMYFUNCTION("""COMPUTED_VALUE"""),"") | R26: =IFERROR(__xludf.DUMMYFUNCTION("""COMPUTED_VALUE"""),"") | S26: =IFERROR(__xludf.DUMMYFUNCTION("""COMPUTED_VALUE"""),"") | T26: =IFERROR(__xludf.DUMMYFUNCTION("""COMPUTED_VALUE"""),"") | U26: =IFERROR(__xludf.DUMMYFUNCTION("""COMPUTED_VALUE"""),"") | V26: =IFERROR(__xludf.DUMMYFUNCTION("""COMPUTED_VALUE"""),"") | W26: =IFERROR(__xludf.DUMMYFUNCTION("""COMPUTED_VALUE"""),"") | X26: =IFERROR(__xludf.DUMMYFUNCTION("""COMPUTED_VALUE"""),"") | ... AN26: =IFERROR(__xludf.DUMMYFUNCTION("""COMPUTED_VALUE"""),"")
A27: SILANG | B27: =IFERROR(__xludf.DUMMYFUNCTION("""COMPUTED_VALUE"""),"MALUKU UTARA") -> MALUKU UTARA | C27: =IFERROR(__xludf.DUMMYFUNCTION("""COMPUTED_VALUE"""),"JS07") -> JS07 | D27: Talis5 Mix | E27: 16 January 2025 | G27: SNMP sudah UP | H27: =AVERAGE(J27:AN27) -> 1 | I27: =IF(H27<75%, "Potensi SP", "") | J27: =IFERROR(__xludf.DUMMYFUNCTION("""COMPUTED_VALUE"""),1.0) -> 1 | K27: =IFERROR(__xludf.DUMMYFUNCTION("""COMPUTED_VALUE"""),1.0) -> 1 | L27: =IFERROR(__xludf.DUMMYFUNCTION("""COMPUTED_VALUE"""),1.0) -> 1 | M27: =IFERROR(__xludf.DUMMYFUNCTION("""COMPUTED_VALUE"""),1.0) -> 1 | N27: =IFERROR(__xludf.DUMMYFUNCTION("""COMPUTED_VALUE"""),1.0) -> 1 | O27: =IFERROR(__xludf.DUMMYFUNCTION("""COMPUTED_VALUE"""),1.0) -> 1 | P27: =IFERROR(__xludf.DUMMYFUNCTION("""COMPUTED_VALUE"""),1.0) -> 1 | Q27: =IFERROR(__xludf.DUMMYFUNCTION("""COMPUTED_VALUE"""),"") | R27: =IFERROR(__xludf.DUMMYFUNCTION("""COMPUTED_VALUE"""),"") | S27: =IFERROR(__xludf.DUMMYFUNCTION("""COMPUTED_VALUE"""),"") | T27: =IFERROR(__xludf.DUMMYFUNCTION("""COMPUTED_VALUE"""),"") | U27: =IFERROR(__xludf.DUMMYFUNCTION("""COMPUTED_VALUE"""),"") | V27: =IFERROR(__xludf.DUMMYFUNCTION("""COMPUTED_VALUE"""),"") | W27: =IFERROR(__xludf.DUMMYFUNCTION("""COMPUTED_VALUE"""),"") | X27: =IFERROR(__xludf.DUMMYFUNCTION("""COMPUTED_VALUE"""),"") | ... AN27: =IFERROR(__xludf.DUMMYFUNCTION("""COMPUTED_VALUE"""),"")
A28: SEKELY | B28: =IFERROR(__xludf.DUMMYFUNCTION("""COMPUTED_VALUE"""),"MALUKU UTARA") -> MALUKU UTARA | C28: =IFERROR(__xludf.DUMMYFUNCTION("""COMPUTED_VALUE"""),"JS119") -> JS119 | D28: JS PRO | H28: =AVERAGE(J28:AN28) -> 1 | I28: =IF(H28<75%, "Potensi SP", "") | J28: =IFERROR(__xludf.DUMMYFUNCTION("""COMPUTED_VALUE"""),1.0) -> 1 | K28: =IFERROR(__xludf.DUMMYFUNCTION("""COMPUTED_VALUE"""),1.0) -> 1 | L28: =IFERROR(__xludf.DUMMYFUNCTION("""COMPUTED_VALUE"""),1.0) -> 1 | M28: =IFERROR(__xludf.DUMMYFUNCTION("""COMPUTED_VALUE"""),1.0) -> 1 | N28: =IFERROR(__xludf.DUMMYFUNCTION("""COMPUTED_VALUE"""),1.0) -> 1 | O28: =IFERROR(__xludf.DUMMYFUNCTION("""COMPUTED_VALUE"""),1.0) -> 1 | P28: =IFERROR(__xludf.DUMMYFUNCTION("""COMPUTED_VALUE"""),1.0) -> 1 | Q28: =IFERROR(__xludf.DUMMYFUNCTION("""COMPUTED_VALUE"""),"") | R28: =IFERROR(__xludf.DUMMYFUNCTION("""COMPUTED_VALUE"""),"") | S28: =IFERROR(__xludf.DUMMYFUNCTION("""COMPUTED_VALUE"""),"") | T28: =IFERROR(__xludf.DUMMYFUNCTION("""COMPUTED_VALUE"""),"") | U28: =IFERROR(__xludf.DUMMYFUNCTION("""COMPUTED_VALUE"""),"") | V28: =IFERROR(__xludf.DUMMYFUNCTION("""COMPUTED_VALUE"""),"") | W28: =IFERROR(__xludf.DUMMYFUNCTION("""COMPUTED_VALUE"""),"") | X28: =IFERROR(__xludf.DUMMYFUNCTION("""COMPUTED_VALUE"""),"") | ... AN28: =IFERROR(__xludf.DUMMYFUNCTION("""COMPUTED_VALUE"""),"")
A29: SOROWAN | B29: =IFERROR(__xludf.DUMMYFUNCTION("""COMPUTED_VALUE"""),"PAPUA BARAT") -> PAPUA BARAT | C29: =IFERROR(__xludf.DUMMYFUNCTION("""COMPUTED_VALUE"""),"JS89") -> JS89 | D29: Talis5 Full | E29: 14 December 2024 | H29: =AVERAGE(J29:AN29) -> 1 | I29: =IF(H29<75%, "Potensi SP", "") | J29: =IFERROR(__xludf.DUMMYFUNCTION("""COMPUTED_VALUE"""),1.0) -> 1 | K29: =IFERROR(__xludf.DUMMYFUNCTION("""COMPUTED_VALUE"""),1.0) -> 1 | L29: =IFERROR(__xludf.DUMMYFUNCTION("""COMPUTED_VALUE"""),1.0) -> 1 | M29: =IFERROR(__xludf.DUMMYFUNCTION("""COMPUTED_VALUE"""),1.0) -> 1 | N29: =IFERROR(__xludf.DUMMYFUNCTION("""COMPUTED_VALUE"""),1.0) -> 1 | O29: =IFERROR(__xludf.DUMMYFUNCTION("""COMPUTED_VALUE"""),1.0) -> 1 | P29: =IFERROR(__xludf.DUMMYFUNCTION("""COMPUTED_VALUE"""),1.0) -> 1 | Q29: =IFERROR(__xludf.DUMMYFUNCTION("""COMPUTED_VALUE"""),"") | R29: =IFERROR(__xludf.DUMMYFUNCTION("""COMPUTED_VALUE"""),"") | S29: =IFERROR(__xludf.DUMMYFUNCTION("""COMPUTED_VALUE"""),"") | T29: =IFERROR(__xludf.DUMMYFUNCTION("""COMPUTED_VALUE"""),"") | U29: =IFERROR(__xludf.DUMMYFUNCTION("""COMPUTED_VALUE"""),"") | V29: =IFERROR(__xludf.DUMMYFUNCTION("""COMPUTED_VALUE"""),"") | W29: =IFERROR(__xludf.DUMMYFUNCTION("""COMPUTED_VALUE"""),"") | X29: =IFERROR(__xludf.DUMMYFUNCTION("""COMPUTED_VALUE"""),"") | ... AN29: =IFERROR(__xludf.DUMMYFUNCTION("""COMPUTED_VALUE"""),"")
A30: TUTUPA | B30: =IFERROR(__xludf.DUMMYFUNCTION("""COMPUTED_VALUE"""),"MALUKU UTARA") -> MALUKU UTARA | C30: =IFERROR(__xludf.DUMMYFUNCTION("""COMPUTED_VALUE"""),"JS16") -> JS16 | D30: JS PRO | G30: VSAT sudah up | H30: =AVERAGE(J30:AN30) -> 0.99801429 | I30: =IF(H30<75%, "Potensi SP", "") | J30: =IFERROR(__xludf.DUMMYFUNCTION("""COMPUTED_VALUE"""),0.99652) -> 0.99652 | K30: =IFERROR(__xludf.DUMMYFUNCTION("""COMPUTED_VALUE"""),1.0) -> 1 | L30: =IFERROR(__xludf.DUMMYFUNCTION("""COMPUTED_VALUE"""),1.0) -> 1 | M30: =IFERROR(__xludf.DUMMYFUNCTION("""COMPUTED_VALUE"""),1.0) -> 1 | N30: =IFERROR(__xludf.DUMMYFUNCTION("""COMPUTED_VALUE"""),0.98958) -> 0.98958 | O30: =IFERROR(__xludf.DUMMYFUNCTION("""COMPUTED_VALUE"""),1.0) -> 1 | P30: =IFERROR(__xludf.DUMMYFUNCTION("""COMPUTED_VALUE"""),1.0) -> 1 | Q30: =IFERROR(__xludf.DUMMYFUNCTION("""COMPUTED_VALUE"""),"") | R30: =IFERROR(__xludf.DUMMYFUNCTION("""COMPUTED_VALUE"""),"") | S30: =IFERROR(__xludf.DUMMYFUNCTION("""COMPUTED_VALUE"""),"") | T30: =IFERROR(__xludf.DUMMYFUNCTION("""COMPUTED_VALUE"""),"") | U30: =IFERROR(__xludf.DUMMYFUNCTION("""COMPUTED_VALUE"""),"") | V30: =IFERROR(__xludf.DUMMYFUNCTION("""COMPUTED_VALUE"""),"") | W30: =IFERROR(__xludf.DUMMYFUNCTION("""COMPUTED_VALUE"""),"") | X30: =IFERROR(__xludf.DUMMYFUNCTION("""COMPUTED_VALUE"""),"") | ... AN30: =IFERROR(__xludf.DUMMYFUNCTION("""COMPUTED_VALUE"""),"")
A31: BOLDON | B31: =IFERROR(__xludf.DUMMYFUNCTION("""COMPUTED_VALUE"""),"PAPUA BARAT") -> PAPUA BARAT | C31: =IFERROR(__xludf.DUMMYFUNCTION("""COMPUTED_VALUE"""),"JS86") -> JS86 | D31: JS PRO | G31: Vsat Sudah up | H31: =AVERAGE(J31:AN31) -> 0.96974143 | I31: =IF(H31<75%, "Potensi SP", "") | J31: =IFERROR(__xludf.DUMMYFUNCTION("""COMPUTED_VALUE"""),1.0) -> 1 | K31: =IFERROR(__xludf.DUMMYFUNCTION("""COMPUTED_VALUE"""),1.0) -> 1 | L31: =IFERROR(__xludf.DUMMYFUNCTION("""COMPUTED_VALUE"""),0.7881900000000001) -> 0.78819 | M31: =IFERROR(__xludf.DUMMYFUNCTION("""COMPUTED_VALUE"""),1.0) -> 1 | N31: =IFERROR(__xludf.DUMMYFUNCTION("""COMPUTED_VALUE"""),1.0) -> 1 | O31: =IFERROR(__xludf.DUMMYFUNCTION("""COMPUTED_VALUE"""),1.0) -> 1 | P31: =IFERROR(__xludf.DUMMYFUNCTION("""COMPUTED_VALUE"""),1.0) -> 1 | Q31: =IFERROR(__xludf.DUMMYFUNCTION("""COMPUTED_VALUE"""),"") | R31: =IFERROR(__xludf.DUMMYFUNCTION("""COMPUTED_VALUE"""),"") | S31: =IFERROR(__xludf.DUMMYFUNCTION("""COMPUTED_VALUE"""),"") | T31: =IFERROR(__xludf.DUMMYFUNCTION("""COMPUTED_VALUE"""),"") | U31: =IFERROR(__xludf.DUMMYFUNCTION("""COMPUTED_VALUE"""),"") | V31: =IFERROR(__xludf.DUMMYFUNCTION("""COMPUTED_VALUE"""),"") | W31: =IFERROR(__xludf.DUMMYFUNCTION("""COMPUTED_VALUE"""),"") | X31: =IFERROR(__xludf.DUMMYFUNCTION("""COMPUTED_VALUE"""),"") | ... AN31: =IFERROR(__xludf.DUMMYFUNCTION("""COMPUTED_VALUE"""),"")
A32: SAYORI SIKAMA | B32: =IFERROR(__xludf.DUMMYFUNCTION("""COMPUTED_VALUE"""),"PAPUA BARAT") -> PAPUA BARAT | C32: =IFERROR(__xludf.DUMMYFUNCTION("""COMPUTED_VALUE"""),"JS23") -> JS23 | D32: Talis5 Full | E32: 06 August 2025 | H32: =AVERAGE(J32:AN32) -> 1 | I32: =IF(H32<75%, "Potensi SP", "") | J32: =IFERROR(__xludf.DUMMYFUNCTION("""COMPUTED_VALUE"""),1.0) -> 1 | K32: =IFERROR(__xludf.DUMMYFUNCTION("""COMPUTED_VALUE"""),1.0) -> 1 | L32: =IFERROR(__xludf.DUMMYFUNCTION("""COMPUTED_VALUE"""),1.0) -> 1 | M32: =IFERROR(__xludf.DUMMYFUNCTION("""COMPUTED_VALUE"""),1.0) -> 1 | N32: =IFERROR(__xludf.DUMMYFUNCTION("""COMPUTED_VALUE"""),1.0) -> 1 | O32: =IFERROR(__xludf.DUMMYFUNCTION("""COMPUTED_VALUE"""),1.0) -> 1 | P32: =IFERROR(__xludf.DUMMYFUNCTION("""COMPUTED_VALUE"""),1.0) -> 1 | Q32: =IFERROR(__xludf.DUMMYFUNCTION("""COMPUTED_VALUE"""),"") | R32: =IFERROR(__xludf.DUMMYFUNCTION("""COMPUTED_VALUE"""),"") | S32: =IFERROR(__xludf.DUMMYFUNCTION("""COMPUTED_VALUE"""),"") | T32: =IFERROR(__xludf.DUMMYFUNCTION("""COMPUTED_VALUE"""),"") | U32: =IFERROR(__xludf.DUMMYFUNCTION("""COMPUTED_VALUE"""),"") | V32: =IFERROR(__xludf.DUMMYFUNCTION("""COMPUTED_VALUE"""),"") | W32: =IFERROR(__xludf.DUMMYFUNCTION("""COMPUTED_VALUE"""),"") | X32: =IFERROR(__xludf.DUMMYFUNCTION("""COMPUTED_VALUE"""),"") | ... AN32: =IFERROR(__xludf.DUMMYFUNCTION("""COMPUTED_VALUE"""),"")
A33: NANIMORI | B33: =IFERROR(__xludf.DUMMYFUNCTION("""COMPUTED_VALUE"""),"PAPUA BARAT") -> PAPUA BARAT | C33: =IFERROR(__xludf.DUMMYFUNCTION("""COMPUTED_VALUE"""),"JS11") -> JS11 | D33: Talis5 Full | E33: 10 August 2025 | H33: =AVERAGE(J33:AN33) -> 1 | I33: =IF(H33<75%, "Potensi SP", "") | J33: =IFERROR(__xludf.DUMMYFUNCTION("""COMPUTED_VALUE"""),1.0) -> 1 | K33: =IFERROR(__xludf.DUMMYFUNCTION("""COMPUTED_VALUE"""),1.0) -> 1 | L33: =IFERROR(__xludf.DUMMYFUNCTION("""COMPUTED_VALUE"""),1.0) -> 1 | M33: =IFERROR(__xludf.DUMMYFUNCTION("""COMPUTED_VALUE"""),1.0) -> 1 | N33: =IFERROR(__xludf.DUMMYFUNCTION("""COMPUTED_VALUE"""),1.0) -> 1 | O33: =IFERROR(__xludf.DUMMYFUNCTION("""COMPUTED_VALUE"""),1.0) -> 1 | P33: =IFERROR(__xludf.DUMMYFUNCTION("""COMPUTED_VALUE"""),1.0) -> 1 | Q33: =IFERROR(__xludf.DUMMYFUNCTION("""COMPUTED_VALUE"""),"") | R33: =IFERROR(__xludf.DUMMYFUNCTION("""COMPUTED_VALUE"""),"") | S33: =IFERROR(__xludf.DUMMYFUNCTION("""COMPUTED_VALUE"""),"") | T33: =IFERROR(__xludf.DUMMYFUNCTION("""COMPUTED_VALUE"""),"") | U33: =IFERROR(__xludf.DUMMYFUNCTION("""COMPUTED_VALUE"""),"") | V33: =IFERROR(__xludf.DUMMYFUNCTION("""COMPUTED_VALUE"""),"") | W33: =IFERROR(__xludf.DUMMYFUNCTION("""COMPUTED_VALUE"""),"") | X33: =IFERROR(__xludf.DUMMYFUNCTION("""COMPUTED_VALUE"""),"") | ... AN33: =IFERROR(__xludf.DUMMYFUNCTION("""COMPUTED_VALUE"""),"")
A34: MARANTUTUL | B34: =IFERROR(__xludf.DUMMYFUNCTION("""COMPUTED_VALUE"""),"MALUKU") -> MALUKU | C34: =IFERROR(__xludf.DUMMYFUNCTION("""COMPUTED_VALUE"""),"JS47") -> JS47 | D34: JS PRO | H34: =AVERAGE(J34:AN34) -> 0.99950286 | I34: =IF(H34<75%, "Potensi SP", "") | J34: =IFERROR(__xludf.DUMMYFUNCTION("""COMPUTED_VALUE"""),1.0) -> 1 | K34: =IFERROR(__xludf.DUMMYFUNCTION("""COMPUTED_VALUE"""),1.0) -> 1 | L34: =IFERROR(__xludf.DUMMYFUNCTION("""COMPUTED_VALUE"""),1.0) -> 1 | M34: =IFERROR(__xludf.DUMMYFUNCTION("""COMPUTED_VALUE"""),0.99652) -> 0.99652 | N34: =IFERROR(__xludf.DUMMYFUNCTION("""COMPUTED_VALUE"""),1.0) -> 1 | O34: =IFERROR(__xludf.DUMMYFUNCTION("""COMPUTED_VALUE"""),1.0) -> 1 | P34: =IFERROR(__xludf.DUMMYFUNCTION("""COMPUTED_VALUE"""),1.0) -> 1 | Q34: =IFERROR(__xludf.DUMMYFUNCTION("""COMPUTED_VALUE"""),"") | R34: =IFERROR(__xludf.DUMMYFUNCTION("""COMPUTED_VALUE"""),"") | S34: =IFERROR(__xludf.DUMMYFUNCTION("""COMPUTED_VALUE"""),"") | T34: =IFERROR(__xludf.DUMMYFUNCTION("""COMPUTED_VALUE"""),"") | U34: =IFERROR(__xludf.DUMMYFUNCTION("""COMPUTED_VALUE"""),"") | V34: =IFERROR(__xludf.DUMMYFUNCTION("""COMPUTED_VALUE"""),"") | W34: =IFERROR(__xludf.DUMMYFUNCTION("""COMPUTED_VALUE"""),"") | X34: =IFERROR(__xludf.DUMMYFUNCTION("""COMPUTED_VALUE"""),"") | ... AN34: =IFERROR(__xludf.DUMMYFUNCTION("""COMPUTED_VALUE"""),"")
A35: TABAJAYA | B35: =IFERROR(__xludf.DUMMYFUNCTION("""COMPUTED_VALUE"""),"MALUKU UTARA") -> MALUKU UTARA | C35: =IFERROR(__xludf.DUMMYFUNCTION("""COMPUTED_VALUE"""),"JS14") -> JS14 | D35: JS PRO | H35: =AVERAGE(J35:AN35) -> 0.99553429 | I35: =IF(H35<75%, "Potensi SP", "") | J35: =IFERROR(__xludf.DUMMYFUNCTION("""COMPUTED_VALUE"""),0.97222) -> 0.97222 | K35: =IFERROR(__xludf.DUMMYFUNCTION("""COMPUTED_VALUE"""),1.0) -> 1 | L35: =IFERROR(__xludf.DUMMYFUNCTION("""COMPUTED_VALUE"""),1.0) -> 1 | M35: =IFERROR(__xludf.DUMMYFUNCTION("""COMPUTED_VALUE"""),1.0) -> 1 | N35: =IFERROR(__xludf.DUMMYFUNCTION("""COMPUTED_VALUE"""),0.99652) -> 0.99652 | O35: =IFERROR(__xludf.DUMMYFUNCTION("""COMPUTED_VALUE"""),1.0) -> 1 | P35: =IFERROR(__xludf.DUMMYFUNCTION("""COMPUTED_VALUE"""),1.0) -> 1 | Q35: =IFERROR(__xludf.DUMMYFUNCTION("""COMPUTED_VALUE"""),"") | R35: =IFERROR(__xludf.DUMMYFUNCTION("""COMPUTED_VALUE"""),"") | S35: =IFERROR(__xludf.DUMMYFUNCTION("""COMPUTED_VALUE"""),"") | T35: =IFERROR(__xludf.DUMMYFUNCTION("""COMPUTED_VALUE"""),"") | U35: =IFERROR(__xludf.DUMMYFUNCTION("""COMPUTED_VALUE"""),"") | V35: =IFERROR(__xludf.DUMMYFUNCTION("""COMPUTED_VALUE"""),"") | W35: =IFERROR(__xludf.DUMMYFUNCTION("""COMPUTED_VALUE"""),"") | X35: =IFERROR(__xludf.DUMMYFUNCTION("""COMPUTED_VALUE"""),"") | ... AN35: =IFERROR(__xludf.DUMMYFUNCTION("""COMPUTED_VALUE"""),"")
A36: SOBIAR | B36: =IFERROR(__xludf.DUMMYFUNCTION("""COMPUTED_VALUE"""),"PAPUA BARAT") -> PAPUA BARAT | C36: =IFERROR(__xludf.DUMMYFUNCTION("""COMPUTED_VALUE"""),"JS09") -> JS09 | D36: JS PRO | H36: =AVERAGE(J36:AN36) -> 1 | I36: =IF(H36<75%, "Potensi SP", "") | J36: =IFERROR(__xludf.DUMMYFUNCTION("""COMPUTED_VALUE"""),1.0) -> 1 | K36: =IFERROR(__xludf.DUMMYFUNCTION("""COMPUTED_VALUE"""),1.0) -> 1 | L36: =IFERROR(__xludf.DUMMYFUNCTION("""COMPUTED_VALUE"""),1.0) -> 1 | M36: =IFERROR(__xludf.DUMMYFUNCTION("""COMPUTED_VALUE"""),1.0) -> 1 | N36: =IFERROR(__xludf.DUMMYFUNCTION("""COMPUTED_VALUE"""),1.0) -> 1 | O36: =IFERROR(__xludf.DUMMYFUNCTION("""COMPUTED_VALUE"""),1.0) -> 1 | P36: =IFERROR(__xludf.DUMMYFUNCTION("""COMPUTED_VALUE"""),1.0) -> 1 | Q36: =IFERROR(__xludf.DUMMYFUNCTION("""COMPUTED_VALUE"""),"") | R36: =IFERROR(__xludf.DUMMYFUNCTION("""COMPUTED_VALUE"""),"") | S36: =IFERROR(__xludf.DUMMYFUNCTION("""COMPUTED_VALUE"""),"") | T36: =IFERROR(__xludf.DUMMYFUNCTION("""COMPUTED_VALUE"""),"") | U36: =IFERROR(__xludf.DUMMYFUNCTION("""COMPUTED_VALUE"""),"") | V36: =IFERROR(__xludf.DUMMYFUNCTION("""COMPUTED_VALUE"""),"") | W36: =IFERROR(__xludf.DUMMYFUNCTION("""COMPUTED_VALUE"""),"") | X36: =IFERROR(__xludf.DUMMYFUNCTION("""COMPUTED_VALUE"""),"") | ... AN36: =IFERROR(__xludf.DUMMYFUNCTION("""COMPUTED_VALUE"""),"")
A37: KLAYILI | B37: =IFERROR(__xludf.DUMMYFUNCTION("""COMPUTED_VALUE"""),"PAPUA BARAT") -> PAPUA BARAT | C37: =IFERROR(__xludf.DUMMYFUNCTION("""COMPUTED_VALUE"""),"JS107") -> JS107 | D37: Talis5 Full | E37: 45617 | G37: vsat sudah up | H37: =AVERAGE(J37:AN37) -> 0.96931571 | I37: =IF(H37<75%, "Potensi SP", "") | J37: =IFERROR(__xludf.DUMMYFUNCTION("""COMPUTED_VALUE"""),1.0) -> 1 | K37: =IFERROR(__xludf.DUMMYFUNCTION("""COMPUTED_VALUE"""),1.0) -> 1 | L37: =IFERROR(__xludf.DUMMYFUNCTION("""COMPUTED_VALUE"""),0.78521) -> 0.78521 | M37: =IFERROR(__xludf.DUMMYFUNCTION("""COMPUTED_VALUE"""),1.0) -> 1 | N37: =IFERROR(__xludf.DUMMYFUNCTION("""COMPUTED_VALUE"""),1.0) -> 1 | O37: =IFERROR(__xludf.DUMMYFUNCTION("""COMPUTED_VALUE"""),1.0) -> 1 | P37: =IFERROR(__xludf.DUMMYFUNCTION("""COMPUTED_VALUE"""),1.0) -> 1 | Q37: =IFERROR(__xludf.DUMMYFUNCTION("""COMPUTED_VALUE"""),"") | R37: =IFERROR(__xludf.DUMMYFUNCTION("""COMPUTED_VALUE"""),"") | S37: =IFERROR(__xludf.DUMMYFUNCTION("""COMPUTED_VALUE"""),"") | T37: =IFERROR(__xludf.DUMMYFUNCTION("""COMPUTED_VALUE"""),"") | U37: =IFERROR(__xludf.DUMMYFUNCTION("""COMPUTED_VALUE"""),"") | V37: =IFERROR(__xludf.DUMMYFUNCTION("""COMPUTED_VALUE"""),"") | W37: =IFERROR(__xludf.DUMMYFUNCTION("""COMPUTED_VALUE"""),"") | X37: =IFERROR(__xludf.DUMMYFUNCTION("""COMPUTED_VALUE"""),"") | ... AN37: =IFERROR(__xludf.DUMMYFUNCTION("""COMPUTED_VALUE"""),"")
A38: KAIREU | B38: =IFERROR(__xludf.DUMMYFUNCTION("""COMPUTED_VALUE"""),"MALUKU") -> MALUKU | C38: =IFERROR(__xludf.DUMMYFUNCTION("""COMPUTED_VALUE"""),"JS128") -> JS128 | D38: JS PRO | H38: =AVERAGE(J38:AN38) -> 1 | I38: =IF(H38<75%, "Potensi SP", "") | J38: =IFERROR(__xludf.DUMMYFUNCTION("""COMPUTED_VALUE"""),1.0) -> 1 | K38: =IFERROR(__xludf.DUMMYFUNCTION("""COMPUTED_VALUE"""),1.0) -> 1 | L38: =IFERROR(__xludf.DUMMYFUNCTION("""COMPUTED_VALUE"""),1.0) -> 1 | M38: =IFERROR(__xludf.DUMMYFUNCTION("""COMPUTED_VALUE"""),1.0) -> 1 | N38: =IFERROR(__xludf.DUMMYFUNCTION("""COMPUTED_VALUE"""),1.0) -> 1 | O38: =IFERROR(__xludf.DUMMYFUNCTION("""COMPUTED_VALUE"""),1.0) -> 1 | P38: =IFERROR(__xludf.DUMMYFUNCTION("""COMPUTED_VALUE"""),1.0) -> 1 | Q38: =IFERROR(__xludf.DUMMYFUNCTION("""COMPUTED_VALUE"""),"") | R38: =IFERROR(__xludf.DUMMYFUNCTION("""COMPUTED_VALUE"""),"") | S38: =IFERROR(__xludf.DUMMYFUNCTION("""COMPUTED_VALUE"""),"") | T38: =IFERROR(__xludf.DUMMYFUNCTION("""COMPUTED_VALUE"""),"") | U38: =IFERROR(__xludf.DUMMYFUNCTION("""COMPUTED_VALUE"""),"") | V38: =IFERROR(__xludf.DUMMYFUNCTION("""COMPUTED_VALUE"""),"") | W38: =IFERROR(__xludf.DUMMYFUNCTION("""COMPUTED_VALUE"""),"") | X38: =IFERROR(__xludf.DUMMYFUNCTION("""COMPUTED_VALUE"""),"") | ... AN38: =IFERROR(__xludf.DUMMYFUNCTION("""COMPUTED_VALUE"""),"")
A39: MITAK KOLAM | B39: =IFERROR(__xludf.DUMMYFUNCTION("""COMPUTED_VALUE"""),"MALUKU") -> MALUKU | C39: =IFERROR(__xludf.DUMMYFUNCTION("""COMPUTED_VALUE"""),"JS44") -> JS44 | D39: Talis5 Mix | E39: 45917 | G39: SOMO POWER Done revit(17 sept 25) | H39: =AVERAGE(J39:AN39) -> 0.99305 | I39: =IF(H39<75%, "Potensi SP", "") | J39: =IFERROR(__xludf.DUMMYFUNCTION("""COMPUTED_VALUE"""),0.9860899999999999) -> 0.98609 | K39: =IFERROR(__xludf.DUMMYFUNCTION("""COMPUTED_VALUE"""),0.9930500000000001) -> 0.99305 | L39: =IFERROR(__xludf.DUMMYFUNCTION("""COMPUTED_VALUE"""),1.0) -> 1 | M39: =IFERROR(__xludf.DUMMYFUNCTION("""COMPUTED_VALUE"""),1.0) -> 1 | N39: =IFERROR(__xludf.DUMMYFUNCTION("""COMPUTED_VALUE"""),0.98263) -> 0.98263 | O39: =IFERROR(__xludf.DUMMYFUNCTION("""COMPUTED_VALUE"""),0.98958) -> 0.98958 | P39: =IFERROR(__xludf.DUMMYFUNCTION("""COMPUTED_VALUE"""),1.0) -> 1 | Q39: =IFERROR(__xludf.DUMMYFUNCTION("""COMPUTED_VALUE"""),"") | R39: =IFERROR(__xludf.DUMMYFUNCTION("""COMPUTED_VALUE"""),"") | S39: =IFERROR(__xludf.DUMMYFUNCTION("""COMPUTED_VALUE"""),"") | T39: =IFERROR(__xludf.DUMMYFUNCTION("""COMPUTED_VALUE"""),"") | U39: =IFERROR(__xludf.DUMMYFUNCTION("""COMPUTED_VALUE"""),"") | V39: =IFERROR(__xludf.DUMMYFUNCTION("""COMPUTED_VALUE"""),"") | W39: =IFERROR(__xludf.DUMMYFUNCTION("""COMPUTED_VALUE"""),"") | X39: =IFERROR(__xludf.DUMMYFUNCTION("""COMPUTED_VALUE"""),"") | ... AN39: =IFERROR(__xludf.DUMMYFUNCTION("""COMPUTED_VALUE"""),"")
A40: ILILI | B40: =IFERROR(__xludf.DUMMYFUNCTION("""COMPUTED_VALUE"""),"MALUKU") -> MALUKU | C40: =IFERROR(__xludf.DUMMYFUNCTION("""COMPUTED_VALUE"""),"JS106") -> JS106 | D40: Talis5 Full | E40: 14 December 2024 | G40: SNMP sudah up ( Done replace) | H40: =AVERAGE(J40:AN40) -> 0.99950143 | I40: =IF(H40<75%, "Potensi SP", "") | J40: =IFERROR(__xludf.DUMMYFUNCTION("""COMPUTED_VALUE"""),1.0) -> 1 | K40: =IFERROR(__xludf.DUMMYFUNCTION("""COMPUTED_VALUE"""),1.0) -> 1 | L40: =IFERROR(__xludf.DUMMYFUNCTION("""COMPUTED_VALUE"""),0.99651) -> 0.99651 | M40: =IFERROR(__xludf.DUMMYFUNCTION("""COMPUTED_VALUE"""),1.0) -> 1 | N40: =IFERROR(__xludf.DUMMYFUNCTION("""COMPUTED_VALUE"""),1.0) -> 1 | O40: =IFERROR(__xludf.DUMMYFUNCTION("""COMPUTED_VALUE"""),1.0) -> 1 | P40: =IFERROR(__xludf.DUMMYFUNCTION("""COMPUTED_VALUE"""),1.0) -> 1 | Q40: =IFERROR(__xludf.DUMMYFUNCTION("""COMPUTED_VALUE"""),"") | R40: =IFERROR(__xludf.DUMMYFUNCTION("""COMPUTED_VALUE"""),"") | S40: =IFERROR(__xludf.DUMMYFUNCTION("""COMPUTED_VALUE"""),"") | T40: =IFERROR(__xludf.DUMMYFUNCTION("""COMPUTED_VALUE"""),"") | U40: =IFERROR(__xludf.DUMMYFUNCTION("""COMPUTED_VALUE"""),"") | V40: =IFERROR(__xludf.DUMMYFUNCTION("""COMPUTED_VALUE"""),"") | W40: =IFERROR(__xludf.DUMMYFUNCTION("""COMPUTED_VALUE"""),"") | X40: =IFERROR(__xludf.DUMMYFUNCTION("""COMPUTED_VALUE"""),"") | ... AN40: =IFERROR(__xludf.DUMMYFUNCTION("""COMPUTED_VALUE"""),"")
...

Sheet siteinfo
B1: SITE SUNDAYA PROJEK BAKTI TAHUN 2025
B2: PROVINSI | C2: TOTAL SITE | D2: BATERAI | E2: TOTAL SITE | F2: LIST SITE
